Workbook
Name \0: #N/A
Name \0_1: #N/A
Name \A: #N/A
Name \a.: #N/A
Name \a._1: #N/A
Name \A_1: #N/A
Name \B: #N/A
Name \b.: #N/A
Name \C: #REF!
Name \C: #REF!
Name \C: #REF!
Name \C: #REF!
Name \C: #REF!
Name \C: #REF!
Name \C_1: #N/A
Name \C_2: #N/A
Name \D: #REF!
Name \D: #REF!
Name \D: #REF!
Name \D: #REF!
Name \D: #REF!
Name \D: #REF!
Name \D_1: #N/A
Name \E: #N/A
Name \E_1: #N/A
Name \E1: #N/A
Name \E1_1: #N/A
Name \F: #N/A
Name \F_1: #N/A
Name \G: #N/A
Name \G_1: #N/A
Name \H: #N/A
Name \H_1: #N/A
Name \I: #REF!
Name \I_1: #N/A
Name \J: #N/A
Name \K: #N/A
Name \L: #N/A
Name \L_1: #N/A
Name \L_2: #N/A
Name \M: #N/A
Name \M_1: #N/A
Name \N: #REF!
Name \N_1: #N/A
Name \O: #N/A
Name \O_1: #N/A
Name \P: #N/A
Name \P_1: #N/A
Name \Q: #REF!
Name \Q_1: #N/A
Name \R: #REF!
Name \R_1: #N/A
Name \S: #N/A
Name \S_1: #N/A
Name \T: #REF!
Name \T_1: #N/A
Name \U: #N/A
Name \U_1: #N/A
Name \V: #N/A
Name \W: #N/A

Sheet BBM Maumere
C2: TABEL PROFITABILITY PROJECT | G2: KESIMPULAN ANALISIS KELAYAKAN PROJECT
C3: INFORMASI PROJECT | G3: =E6 -> Pekerjaan Pengadaan BBM TTC Maumere
C4: Nama Pelanggan | E4: Telkomsel | G4: =E4 -> Telkomsel
C5: Kategori Project | E5: PS | G5: REVENUE | I5: =IF(E37=D55,E37,"perhitungan salah, CEK KEMBALI CASH FLOW DAN BLOCK REVENUE STREAM") -> 44146500 | J5: =I5=E37 -> TRUE
C6: Nama Project | E6: Pekerjaan Pengadaan BBM TTC Maumere | G6: TOTAL BEBAN/CASH OUT | I6: =IF(E23=D58*-1,E23,"perhitungan salah, CEK KEMBALI CASH FLOW DAN BLOCKCOST STRUCTURE") -> 32973000 | J6: =I6=E23 -> TRUE
C7: Lokasi Project | E7: TTC Maumere | G7: GROSS MARGIN | H7: =I7/I5 -> 0.25310047 | I7: =I5-I6 -> 11173500 | J7: =I7=D67 -> TRUE
C8: Estimasi mulai pekerjaan (MM/YY) | E8: 46259 | G8: Total Pajak PPH | I8: =E41 -> 1169882.3 | J8: =I8=E41 -> TRUE
A9: =IF(E9="",0,1) -> 1 | C9: Durasi Project (bulan) | E9: 1 | G9: GROSS MARGIN + PPH | H9: =I9/I5 -> 0.22660047 | I9: =I7-I8 -> 10003618 | J9: =I9=D73 -> TRUE
A10: =IF(E10="",0,1) -> 1 | C10: Durasi Retensi (bulan) | E10: 0 | G10: Provisi | I10: =D76*-1 -> 7284.1725 | J10: =I10=E45 -> TRUE
C11: Pengawasan Konstruksi Sendiri / Menggunakan MK ? | E11: Sendiri ( by GSD ) | F11: *pilihan | G11: Bunga Pinjaman | I11: =D77*-1 -> 6610.3865 | J11: =I11=E46 -> TRUE
C12: Tipe Bagunan | D12: {=IF(E37<='[128]Tabel PUPR'!A15,'[128]Tabel PUPR'!B15,IF(E37<='[128]Tabel PUPR'!A16,'[128]Tabel PUPR'!B16,IF(E37<='[128]Tabel PUPR'!A17,'[128]Tabel PUPR'!B17,IF(E37<='[128]Tabel PUPR'!A18,'[128]Tabel PUPR'!B18,IF(E37<='[128]Tabel PUPR'!A19,'[128]Tabel PUPR'!B19,IF(E37<='[128]Tabel PUPR'!A20,'[128]Tabel PUPR'!B20,IF(E37<='[128]Tabel PUPR'!A21,'[128]Tabel PUPR'!B21,IF(E37<='[128]Tabel PUPR'!A22,'[128]Tabel PUPR'!B22,IF(E37<='[128]Tabel PUPR'!A23,'[128]Tabel PUPR'!B23,IF(E37<='[128]Tabel PUPR'!A24,'[128]Tabel PUPR'!B24,IF(E37<='[128]Tabel PUPR'!A25,k,k)))))))))))} -> a | E12: Sederhana ( < 2 lantai) | F12: *pilihan | G12: NET INCOME | H12: =I12/I5 -> 0.22628573 | I12: =I9-SUM(I10:I11) -> 9989723.2
C13: TOP Pembayaran Kepada Mitra | E13: setelah BAST | G13: Kredit PPN | I13: =-D72 -> 1229085
C14: TOP Pembayaran Pelanggan | E14: setelah BAST | G14: NET CASH FLOW | H14: =IF(I14>0,"Cashflow Positif","Cashflow Negatif") -> Cashflow Positif | I14: =I12-I13 -> 8760638.2 | K14: CATATAN:
C15: ASUMSI-ASUMSI | G15: CF selama kontrak | H15: =COUNTIF(E79:Q79,"<"&0) -> 0 | I15: =IF(H15>0,"Terdapat CF Negatif","All CF Positif") -> All CF Positif
A16: =IF(E10=[129]key!A3,1,0) -> 0 | C16: Suku Bunga per tahun | E16: 0.1089 | G16: KESIMPULAN | H16: =IF(H12>0%,IF(H15=0,IF(H12>10.89%,"Layak dengan Net Income sebesar",IF(I5>1000000000,IF(H12>10.89%,"Tidak Layak dengan Net income dibawah treshold ",IF(H12>0%,"Tidak Layak dengan Net income dibawah treshold","Tidak Layak dengan Net income dibawah treshold")),"Tidak Layak dengan Net income dibawah treshold")),"Tidak Layak dengan Net Income sebesar"),"Tidak Layak dengan Net income dibawah treshold") -> Layak dengan Net Income sebesar | K16: * JIKA TERDAPAT CF NEGATIF :
C17: Suku Bunga per bulan | E17: =E16/12 -> 0.009075 | H17: =H12 -> 0.22628573 | K17: 1. adjust nilai pinjaman hingga CF positif
C18: Pemodalan: Loan | E18: 1 | G18: REVENUE INCL PPN | H18: 11/12*12% | I18: =I5+D70 -> 49002615 | K18: 2. Adjust asumsi pembayaran mitra / customer, namun harus sesuai dengan
C19: Provisi | E19: 0.01 | G19: Notes lain-lain: | K19: kondisi aktual / konfirmasi dengan pihak OM
C20: PPN | E20: 0.12 | G20: =C24 -> Biaya Mitra Pelaksana (Exclude PPN) | I20: =E24 -> 32973000
C21: PPH pasal 23 | E21: 0.0265 | G21: =C31 -> BOP Project | I21: =E31 -> 0
C22: Periode Pinjaman (Bulan) | E22: =E9 -> 1 | G22: =C39 -> Management Fee GSD | I22: =E39 -> 11173500
C23: COST STRUCTURE / CASH OUT | E23: =SUM(E24:E31) -> 32973000
C24: Biaya Mitra Pelaksana (Exclude PPN) | E24: =COGS!H6 -> 32973000
C25: BEBAN LAINNYA | E25: 0
C26: Fee Fasilitas Jaminan | F26: * Minimal 500rb dengan catatan apabila contohnya: 1. Nilai Proyek 10M 2. Jangka waktu kerjasama adalah 3 bulan 3. Nilai Jaminan Dipersyaratkan 15% Maka Cost untuk fee: =(((0.5%/12)x3)x(15%x10M)
C27: Admin Fasilitas Jaminan | F27: * Apabila ada jaminan, biaya admin Rp 250.000,-
C28: Construction Assurance Risk ( CAR) | E28: 0
C29: Iuran Jasa Konstruksi | E29: 0
C30: Biaya Pengawasan | D30: =IF(E11='[128]Tabel PUPR'!D4,0%,VLOOKUP([128]Profitability!D12,'[128]Tabel PUPR'!B15:E25,IF([128]Profitability!E12='[128]Tabel PUPR'!A8,2,IF([128]Profitability!D12='[128]Tabel PUPR'!A9,3,4)))) -> 0 | E30: =D30*$E$24 -> 0 | F30: Berdasarkan PUPR : | G30: 0
C31: BOP Project | D31: =G31 -> 0 | E31: =D31*$E$24 -> 0 | F31: Berdasarkan PUPR : | G31: 0 | H31: *% bisa disesuaikan dengan asumsi sendiri pada kolom D31
C32: JAMINAN - JAMINAN | E32: =SUM(E33:E36) -> 0
C33: Jaminan Uang muka | D33: 0 | E33: =D33*$E$37 -> 0 | F33: * cek dan sesuaikan pengenaan % terhadap revenue / isi nilai manual pada kolom E
C34: Jaminan Penawaran | D34: 0 | E34: =D34*$E$37 -> 0 | F34: * cek dan sesuaikan pengenaan % terhadap revenue / isi nilai manual pada kolom E
C35: Jaminan Pelaksanaan | D35: 0 | E35: =D35*$E$37 -> 0 | F35: * cek dan sesuaikan pengenaan % terhadap revenue / isi nilai manual pada kolom E
C36: Jaminan Pemeliharaan | D36: 0 | E36: =D36*$E$37 -> 0 | F36: * cek dan sesuaikan pengenaan % terhadap revenue / isi nilai manual pada kolom E
C37: REVENUE STREAM / CASH IN | E37: =SUM(E38:E39) -> 44146500 | G37: 44146500
C38: Jasa Pelaksanaan konstruksi | E38: =E24 -> 32973000
C39: Management Fee GSD | D39: 0.33886816 | E39: =D39*SUM(E38) -> 11173500 | F39: *terhadap nilai mitra
C40: PERPAJAKAN
C41: PPh | E41: =D68*-1 -> 1169882.3
...

Sheet BBM HRM
C2: TABEL PROFITABILITY PROJECT | G2: KESIMPULAN ANALISIS KELAYAKAN PROJECT
C3: INFORMASI PROJECT | G3: =E6 -> Pekerjaan Pengadaan BBM TTC HR Muh
C4: Nama Pelanggan | E4: Telkomsel | G4: =E4 -> Telkomsel
C5: Kategori Project | E5: PS | G5: REVENUE | I5: =IF(E37=D55,E37,"perhitungan salah, CEK KEMBALI CASH FLOW DAN BLOCK REVENUE STREAM") -> 29431000 | J5: =I5=E37 -> TRUE
C6: Nama Project | E6: Pekerjaan Pengadaan BBM TTC HR Muh | G6: TOTAL BEBAN/CASH OUT | I6: =IF(E23=D58*-1,E23,"perhitungan salah, CEK KEMBALI CASH FLOW DAN BLOCKCOST STRUCTURE") -> 22522523 | J6: =I6=E23 -> TRUE
C7: Lokasi Project | E7: TTC HR Muh | G7: GROSS MARGIN | H7: =I7/I5 -> 0.23473472 | I7: =I5-I6 -> 6908477.5 | J7: =I7=D67 -> TRUE
C8: Estimasi mulai pekerjaan (MM/YY) | E8: 46259 | G8: Total Pajak PPH | I8: =E41 -> 779921.5 | J8: =I8=E41 -> TRUE
A9: =IF(E9="",0,1) -> 1 | C9: Durasi Project (bulan) | E9: 1 | G9: GROSS MARGIN + PPH | H9: =I9/I5 -> 0.20823472 | I9: =I7-I8 -> 6128556
A10: =IF(E10="",0,1) -> 1 | C10: Durasi Retensi (bulan) | E10: 0 | G10: Provisi | I10: =D76*-1 -> 4856.115 | J10: =I10=E45 -> TRUE
C11: Pengawasan Konstruksi Sendiri / Menggunakan MK ? | E11: Sendiri ( by GSD ) | F11: *pilihan | G11: Bunga Pinjaman | I11: =D77*-1 -> 4406.9244 | J11: =I11=E46 -> TRUE
C12: Tipe Bagunan | D12: {=IF(E37<='[128]Tabel PUPR'!A15,'[128]Tabel PUPR'!B15,IF(E37<='[128]Tabel PUPR'!A16,'[128]Tabel PUPR'!B16,IF(E37<='[128]Tabel PUPR'!A17,'[128]Tabel PUPR'!B17,IF(E37<='[128]Tabel PUPR'!A18,'[128]Tabel PUPR'!B18,IF(E37<='[128]Tabel PUPR'!A19,'[128]Tabel PUPR'!B19,IF(E37<='[128]Tabel PUPR'!A20,'[128]Tabel PUPR'!B20,IF(E37<='[128]Tabel PUPR'!A21,'[128]Tabel PUPR'!B21,IF(E37<='[128]Tabel PUPR'!A22,'[128]Tabel PUPR'!B22,IF(E37<='[128]Tabel PUPR'!A23,'[128]Tabel PUPR'!B23,IF(E37<='[128]Tabel PUPR'!A24,'[128]Tabel PUPR'!B24,IF(E37<='[128]Tabel PUPR'!A25,k,k)))))))))))} -> a | E12: Sederhana ( < 2 lantai) | F12: *pilihan | G12: NET INCOME | H12: =I12/I5 -> 0.20791998 | I12: =I9-SUM(I10:I11) -> 6119292.9
C13: TOP Pembayaran Kepada Mitra | E13: setelah BAST | G13: Kredit PPN | I13: =-D72 -> 759932.52
C14: TOP Pembayaran Pelanggan | E14: setelah BAST | G14: NET CASH FLOW | H14: =IF(I14>0,"Cashflow Positif","Cashflow Negatif") -> Cashflow Positif | I14: =I12-I13 -> 5359360.4 | K14: CATATAN:
C15: ASUMSI-ASUMSI | G15: CF selama kontrak | H15: =COUNTIF(E79:Q79,"<"&0) -> 0 | I15: =IF(H15>0,"Terdapat CF Negatif","All CF Positif") -> All CF Positif
A16: =IF(E10=[129]key!A3,1,0) -> 0 | C16: Suku Bunga per tahun | E16: 0.1089 | G16: KESIMPULAN | H16: =IF(H12>0%,IF(H15=0,IF(H12>10.89%,"Layak dengan Net Income sebesar",IF(I5>1000000000,IF(H12>10.89%,"Tidak Layak dengan Net income dibawah treshold ",IF(H12>0%,"Tidak Layak dengan Net income dibawah treshold","Tidak Layak dengan Net income dibawah treshold")),"Tidak Layak dengan Net income dibawah treshold")),"Tidak Layak dengan Net Income sebesar"),"Tidak Layak dengan Net income dibawah treshold") -> Layak dengan Net Income sebesar | K16: * JIKA TERDAPAT CF NEGATIF :
C17: Suku Bunga per bulan | E17: =E16/12 -> 0.009075 | H17: =H12 -> 0.20791998 | K17: 1. adjust nilai pinjaman hingga CF positif
C18: Pemodalan: Loan | E18: 1 | G18: REVENUE INCL PPN | H18: 11/12*12% | I18: =I5+D70 -> 32668410 | K18: 2. Adjust asumsi pembayaran mitra / customer, namun harus sesuai dengan
C19: Provisi | E19: 0.01 | G19: Notes lain-lain: | K19: kondisi aktual / konfirmasi dengan pihak OM
C20: PPN | E20: 0.12 | G20: =C24 -> Biaya Mitra Pelaksana (Exclude PPN) | I20: =E24 -> 22522523
C21: PPH pasal 23 | E21: 0.0265 | G21: =C31 -> BOP Project | I21: =E31 -> 0
C22: Periode Pinjaman (Bulan) | E22: =E9 -> 1 | G22: =C39 -> Management Fee GSD | I22: =E39 -> 6908477.5
C23: COST STRUCTURE / CASH OUT | E23: =SUM(E24:E31) -> 22522523
C24: Biaya Mitra Pelaksana (Exclude PPN) | E24: =COGS!H7 -> 22522523
C25: BEBAN LAINNYA | E25: 0
C26: Fee Fasilitas Jaminan | F26: * Minimal 500rb dengan catatan apabila contohnya: 1. Nilai Proyek 10M 2. Jangka waktu kerjasama adalah 3 bulan 3. Nilai Jaminan Dipersyaratkan 15% Maka Cost untuk fee: =(((0.5%/12)x3)x(15%x10M)
C27: Admin Fasilitas Jaminan | F27: * Apabila ada jaminan, biaya admin Rp 250.000,-
C28: Construction Assurance Risk ( CAR) | E28: 0
C29: Iuran Jasa Konstruksi | E29: 0
C30: Biaya Pengawasan | D30: =IF(E11='[128]Tabel PUPR'!D4,0%,VLOOKUP([128]Profitability!D12,'[128]Tabel PUPR'!B15:E25,IF([128]Profitability!E12='[128]Tabel PUPR'!A8,2,IF([128]Profitability!D12='[128]Tabel PUPR'!A9,3,4)))) -> 0 | E30: =D30*$E$24 -> 0 | F30: Berdasarkan PUPR : | G30: 0
C31: BOP Project | D31: =G31 -> 0 | E31: =D31*$E$24 -> 0 | F31: Berdasarkan PUPR : | G31: 0 | H31: *% bisa disesuaikan dengan asumsi sendiri pada kolom D31
C32: JAMINAN - JAMINAN | E32: =SUM(E33:E36) -> 0
C33: Jaminan Uang muka | D33: 0 | E33: =D33*$E$37 -> 0 | F33: * cek dan sesuaikan pengenaan % terhadap revenue / isi nilai manual pada kolom E
C34: Jaminan Penawaran | D34: 0 | E34: =D34*$E$37 -> 0 | F34: * cek dan sesuaikan pengenaan % terhadap revenue / isi nilai manual pada kolom E
C35: Jaminan Pelaksanaan | D35: 0 | E35: =D35*$E$37 -> 0 | F35: * cek dan sesuaikan pengenaan % terhadap revenue / isi nilai manual pada kolom E
C36: Jaminan Pemeliharaan | D36: 0 | E36: =D36*$E$37 -> 0 | F36: * cek dan sesuaikan pengenaan % terhadap revenue / isi nilai manual pada kolom E
C37: REVENUE STREAM / CASH IN | E37: =SUM(E38:E39) -> 29431000 | G37: 29431000
C38: Jasa Pelaksanaan konstruksi | E38: =E24 -> 22522523
C39: Management Fee GSD | D39: 0.3067364 | E39: =D39*SUM(E38) -> 6908477.5 | F39: *terhadap nilai mitra
C40: PERPAJAKAN
C41: PPh | E41: =D68*-1 -> 779921.5
...

Sheet BBM Gayungan
C2: TABEL PROFITABILITY PROJECT | G2: KESIMPULAN ANALISIS KELAYAKAN PROJECT
C3: INFORMASI PROJECT | G3: =E6 -> Pekerjaan Pengadaan BBM TTC Gayungan
C4: Nama Pelanggan | E4: Telkomsel | G4: =E4 -> Telkomsel
C5: Kategori Project | E5: PS | G5: REVENUE | I5: =IF(E37=D55,E37,"perhitungan salah, CEK KEMBALI CASH FLOW DAN BLOCK REVENUE STREAM") -> 1.17724e+08 | J5: =I5=E37 -> TRUE
C6: Nama Project | E6: Pekerjaan Pengadaan BBM TTC Gayungan | G6: TOTAL BEBAN/CASH OUT | I6: =IF(E23=D58*-1,E23,"perhitungan salah, CEK KEMBALI CASH FLOW DAN BLOCKCOST STRUCTURE") -> 90090090 | J6: =I6=E23 -> TRUE
C7: Lokasi Project | E7: TTC Gayungan | G7: GROSS MARGIN | H7: =I7/I5 -> 0.23473472 | I7: =I5-I6 -> 27633910 | J7: =I7=D67 -> TRUE
C8: Estimasi mulai pekerjaan (MM/YY) | E8: 46259 | G8: Total Pajak PPH | I8: =E41 -> 3119686 | J8: =I8=E41 -> TRUE
A9: =IF(E9="",0,1) -> 1 | C9: Durasi Project (bulan) | E9: 1 | G9: GROSS MARGIN + PPH | H9: =I9/I5 -> 0.20823472 | I9: =I7-I8 -> 24514224
A10: =IF(E10="",0,1) -> 1 | C10: Durasi Retensi (bulan) | E10: 0 | G10: Provisi | I10: =D76*-1 -> 19424.46 | J10: =I10=E45 -> TRUE
C11: Pengawasan Konstruksi Sendiri / Menggunakan MK ? | E11: Sendiri ( by GSD ) | F11: *pilihan | G11: Bunga Pinjaman | I11: =D77*-1 -> 17627.697 | J11: =I11=E46 -> TRUE
C12: Tipe Bagunan | D12: {=IF(E37<='[128]Tabel PUPR'!A15,'[128]Tabel PUPR'!B15,IF(E37<='[128]Tabel PUPR'!A16,'[128]Tabel PUPR'!B16,IF(E37<='[128]Tabel PUPR'!A17,'[128]Tabel PUPR'!B17,IF(E37<='[128]Tabel PUPR'!A18,'[128]Tabel PUPR'!B18,IF(E37<='[128]Tabel PUPR'!A19,'[128]Tabel PUPR'!B19,IF(E37<='[128]Tabel PUPR'!A20,'[128]Tabel PUPR'!B20,IF(E37<='[128]Tabel PUPR'!A21,'[128]Tabel PUPR'!B21,IF(E37<='[128]Tabel PUPR'!A22,'[128]Tabel PUPR'!B22,IF(E37<='[128]Tabel PUPR'!A23,'[128]Tabel PUPR'!B23,IF(E37<='[128]Tabel PUPR'!A24,'[128]Tabel PUPR'!B24,IF(E37<='[128]Tabel PUPR'!A25,k,k)))))))))))} -> a | E12: Sederhana ( < 2 lantai) | F12: *pilihan | G12: NET INCOME | H12: =I12/I5 -> 0.20791998 | I12: =I9-SUM(I10:I11) -> 24477172
C13: TOP Pembayaran Kepada Mitra | E13: setelah BAST | G13: Kredit PPN | I13: =-D72 -> 3039730.1
C14: TOP Pembayaran Pelanggan | E14: setelah BAST | G14: NET CASH FLOW | H14: =IF(I14>0,"Cashflow Positif","Cashflow Negatif") -> Cashflow Positif | I14: =I12-I13 -> 21437442 | K14: CATATAN:
C15: ASUMSI-ASUMSI | G15: CF selama kontrak | H15: =COUNTIF(E79:Q79,"<"&0) -> 0 | I15: =IF(H15>0,"Terdapat CF Negatif","All CF Positif") -> All CF Positif
A16: =IF(E10=[129]key!A3,1,0) -> 0 | C16: Suku Bunga per tahun | E16: 0.1089 | G16: KESIMPULAN | H16: =IF(H12>0%,IF(H15=0,IF(H12>10.89%,"Layak dengan Net Income sebesar",IF(I5>1000000000,IF(H12>10.89%,"Tidak Layak dengan Net income dibawah treshold ",IF(H12>0%,"Tidak Layak dengan Net income dibawah treshold","Tidak Layak dengan Net income dibawah treshold")),"Tidak Layak dengan Net income dibawah treshold")),"Tidak Layak dengan Net Income sebesar"),"Tidak Layak dengan Net income dibawah treshold") -> Layak dengan Net Income sebesar | K16: * JIKA TERDAPAT CF NEGATIF :
C17: Suku Bunga per bulan | E17: =E16/12 -> 0.009075 | H17: =H12 -> 0.20791998 | K17: 1. adjust nilai pinjaman hingga CF positif
C18: Pemodalan: Loan | E18: 1 | G18: REVENUE INCL PPN | H18: 11/12*12% | I18: =I5+D70 -> 1.3067364e+08 | K18: 2. Adjust asumsi pembayaran mitra / customer, namun harus sesuai dengan
C19: Provisi | E19: 0.01 | G19: Notes lain-lain: | K19: kondisi aktual / konfirmasi dengan pihak OM
C20: PPN | E20: 0.12 | G20: =C24 -> Biaya Mitra Pelaksana (Exclude PPN) | I20: =E24 -> 90090090
C21: PPH pasal 23 | E21: 0.0265 | G21: =C31 -> BOP Project | I21: =E31 -> 0
C22: Periode Pinjaman (Bulan) | E22: =E9 -> 1 | G22: =C39 -> Management Fee GSD | I22: =E39 -> 27633910
C23: COST STRUCTURE / CASH OUT | E23: =SUM(E24:E31) -> 90090090
C24: Biaya Mitra Pelaksana (Exclude PPN) | E24: =COGS!H8 -> 90090090
C25: BEBAN LAINNYA | E25: 0
C26: Fee Fasilitas Jaminan | F26: * Minimal 500rb dengan catatan apabila contohnya: 1. Nilai Proyek 10M 2. Jangka waktu kerjasama adalah 3 bulan 3. Nilai Jaminan Dipersyaratkan 15% Maka Cost untuk fee: =(((0.5%/12)x3)x(15%x10M)
C27: Admin Fasilitas Jaminan | F27: * Apabila ada jaminan, biaya admin Rp 250.000,-
C28: Construction Assurance Risk ( CAR) | E28: 0
C29: Iuran Jasa Konstruksi | E29: 0
C30: Biaya Pengawasan | D30: =IF(E11='[128]Tabel PUPR'!D4,0%,VLOOKUP([128]Profitability!D12,'[128]Tabel PUPR'!B15:E25,IF([128]Profitability!E12='[128]Tabel PUPR'!A8,2,IF([128]Profitability!D12='[128]Tabel PUPR'!A9,3,4)))) -> 0 | E30: =D30*$E$24 -> 0 | F30: Berdasarkan PUPR : | G30: 0
C31: BOP Project | D31: =G31 -> 0 | E31: =D31*$E$24 -> 0 | F31: Berdasarkan PUPR : | G31: 0 | H31: *% bisa disesuaikan dengan asumsi sendiri pada kolom D31
C32: JAMINAN - JAMINAN | E32: =SUM(E33:E36) -> 0
C33: Jaminan Uang muka | D33: 0 | E33: =D33*$E$37 -> 0 | F33: * cek dan sesuaikan pengenaan % terhadap revenue / isi nilai manual pada kolom E
C34: Jaminan Penawaran | D34: 0 | E34: =D34*$E$37 -> 0 | F34: * cek dan sesuaikan pengenaan % terhadap revenue / isi nilai manual pada kolom E
C35: Jaminan Pelaksanaan | D35: 0 | E35: =D35*$E$37 -> 0 | F35: * cek dan sesuaikan pengenaan % terhadap revenue / isi nilai manual pada kolom E
C36: Jaminan Pemeliharaan | D36: 0 | E36: =D36*$E$37 -> 0 | F36: * cek dan sesuaikan pengenaan % terhadap revenue / isi nilai manual pada kolom E
C37: REVENUE STREAM / CASH IN | E37: =SUM(E38:E39) -> 1.17724e+08 | G37: 117724000
C38: Jasa Pelaksanaan konstruksi | E38: =E24 -> 90090090
C39: Management Fee GSD | D39: 0.3067364 | E39: =D39*SUM(E38) -> 27633910 | F39: *terhadap nilai mitra
C40: PERPAJAKAN
C41: PPh | E41: =D68*-1 -> 3119686
...

Sheet BBM Palapa Kupang
C2: TABEL PROFITABILITY PROJECT | G2: KESIMPULAN ANALISIS KELAYAKAN PROJECT
C3: INFORMASI PROJECT | G3: =E6 -> Pekerjaan Pengadaan BBM TTC Palapa
C4: Nama Pelanggan | E4: Telkomsel | G4: =E4 -> Telkomsel
C5: Kategori Project | E5: PS | G5: REVENUE | I5: =IF(E37=D55,E37,"perhitungan salah, CEK KEMBALI CASH FLOW DAN BLOCK REVENUE STREAM") -> 29431250 | J5: =I5=E37 -> TRUE
C6: Nama Project | E6: Pekerjaan Pengadaan BBM TTC Palapa | G6: TOTAL BEBAN/CASH OUT | I6: =IF(E23=D58*-1,E23,"perhitungan salah, CEK KEMBALI CASH FLOW DAN BLOCKCOST STRUCTURE") -> 21982187 | J6: =I6=E23 -> TRUE
C7: Lokasi Project | E7: Kupang | G7: GROSS MARGIN | H7: =I7/I5 -> 0.25310047 | I7: =I5-I6 -> 7449063.3 | J7: =I7=D67 -> TRUE
C8: Estimasi mulai pekerjaan (MM/YY) | E8: 46259 | G8: Total Pajak PPH | I8: =E41 -> 779928.12 | J8: =I8=E41 -> TRUE
A9: =IF(E9="",0,1) -> 1 | C9: Durasi Project (bulan) | E9: 1 | G9: GROSS MARGIN + PPH | H9: =I9/I5 -> 0.22660047 | I9: =I7-I8 -> 6669135.2
A10: =IF(E10="",0,1) -> 1 | C10: Durasi Retensi (bulan) | E10: 0 | G10: Provisi | I10: =D76*-1 -> 4856.1562 | J10: =I10=E45 -> TRUE
C11: Pengawasan Konstruksi Sendiri / Menggunakan MK ? | E11: Sendiri ( by GSD ) | F11: *pilihan | G11: Bunga Pinjaman | I11: =D77*-1 -> 4406.9618 | J11: =I11=E46 -> TRUE
C12: Tipe Bagunan | D12: {=IF(E37<='[128]Tabel PUPR'!A15,'[128]Tabel PUPR'!B15,IF(E37<='[128]Tabel PUPR'!A16,'[128]Tabel PUPR'!B16,IF(E37<='[128]Tabel PUPR'!A17,'[128]Tabel PUPR'!B17,IF(E37<='[128]Tabel PUPR'!A18,'[128]Tabel PUPR'!B18,IF(E37<='[128]Tabel PUPR'!A19,'[128]Tabel PUPR'!B19,IF(E37<='[128]Tabel PUPR'!A20,'[128]Tabel PUPR'!B20,IF(E37<='[128]Tabel PUPR'!A21,'[128]Tabel PUPR'!B21,IF(E37<='[128]Tabel PUPR'!A22,'[128]Tabel PUPR'!B22,IF(E37<='[128]Tabel PUPR'!A23,'[128]Tabel PUPR'!B23,IF(E37<='[128]Tabel PUPR'!A24,'[128]Tabel PUPR'!B24,IF(E37<='[128]Tabel PUPR'!A25,k,k)))))))))))} -> a | E12: Sederhana ( < 2 lantai) | F12: *pilihan | G12: NET INCOME | H12: =I12/I5 -> 0.22628573 | I12: =I9-SUM(I10:I11) -> 6659872
C13: TOP Pembayaran Kepada Mitra | E13: setelah BAST | G13: Kredit PPN | I13: =-D72 -> 819396.96
C14: TOP Pembayaran Pelanggan | E14: setelah BAST | G14: NET CASH FLOW | H14: =IF(I14>0,"Cashflow Positif","Cashflow Negatif") -> Cashflow Positif | I14: =I12-I13 -> 5840475.1 | K14: CATATAN:
C15: ASUMSI-ASUMSI | G15: CF selama kontrak | H15: =COUNTIF(E79:Q79,"<"&0) -> 0 | I15: =IF(H15>0,"Terdapat CF Negatif","All CF Positif") -> All CF Positif
A16: =IF(E10=[129]key!A3,1,0) -> 0 | C16: Suku Bunga per tahun | E16: 0.1089 | G16: KESIMPULAN | H16: =IF(H12>0%,IF(H15=0,IF(H12>10.89%,"Layak dengan Net Income sebesar",IF(I5>1000000000,IF(H12>10.89%,"Tidak Layak dengan Net income dibawah treshold ",IF(H12>0%,"Tidak Layak dengan Net income dibawah treshold","Tidak Layak dengan Net income dibawah treshold")),"Tidak Layak dengan Net income dibawah treshold")),"Tidak Layak dengan Net Income sebesar"),"Tidak Layak dengan Net income dibawah treshold") -> Layak dengan Net Income sebesar | K16: * JIKA TERDAPAT CF NEGATIF :
C17: Suku Bunga per bulan | E17: =E16/12 -> 0.009075 | H17: =H12 -> 0.22628573 | K17: 1. adjust nilai pinjaman hingga CF positif
C18: Pemodalan: Loan | E18: 1 | G18: REVENUE INCL PPN | H18: 11/12*12% | I18: =I5+D70 -> 32668688 | K18: 2. Adjust asumsi pembayaran mitra / customer, namun harus sesuai dengan
C19: Provisi | E19: 0.01 | G19: Notes lain-lain: | K19: kondisi aktual / konfirmasi dengan pihak OM
C20: PPN | E20: 0.12 | G20: =C24 -> Biaya Mitra Pelaksana (Exclude PPN) | I20: =E24 -> 21982187
C21: PPH pasal 23 | E21: 0.0265 | G21: =C31 -> BOP Project | I21: =E31 -> 0
C22: Periode Pinjaman (Bulan) | E22: =E9 -> 1 | G22: =C39 -> Management Fee GSD | I22: =E39 -> 7449063.3
C23: COST STRUCTURE / CASH OUT | E23: =SUM(E24:E31) -> 21982187
C24: Biaya Mitra Pelaksana (Exclude PPN) | E24: =COGS!H9 -> 21982187
C25: BEBAN LAINNYA | E25: 0
C26: Fee Fasilitas Jaminan | F26: * Minimal 500rb dengan catatan apabila contohnya: 1. Nilai Proyek 10M 2. Jangka waktu kerjasama adalah 3 bulan 3. Nilai Jaminan Dipersyaratkan 15% Maka Cost untuk fee: =(((0.5%/12)x3)x(15%x10M)
C27: Admin Fasilitas Jaminan | F27: * Apabila ada jaminan, biaya admin Rp 250.000,-
C28: Construction Assurance Risk ( CAR) | E28: 0
C29: Iuran Jasa Konstruksi | E29: 0
C30: Biaya Pengawasan | D30: =IF(E11='[128]Tabel PUPR'!D4,0%,VLOOKUP([128]Profitability!D12,'[128]Tabel PUPR'!B15:E25,IF([128]Profitability!E12='[128]Tabel PUPR'!A8,2,IF([128]Profitability!D12='[128]Tabel PUPR'!A9,3,4)))) -> 0 | E30: =D30*$E$24 -> 0 | F30: Berdasarkan PUPR : | G30: 0
C31: BOP Project | D31: =G31 -> 0 | E31: =D31*$E$24 -> 0 | F31: Berdasarkan PUPR : | G31: 0 | H31: *% bisa disesuaikan dengan asumsi sendiri pada kolom D31
C32: JAMINAN - JAMINAN | E32: =SUM(E33:E36) -> 0
C33: Jaminan Uang muka | D33: 0 | E33: =D33*$E$37 -> 0 | F33: * cek dan sesuaikan pengenaan % terhadap revenue / isi nilai manual pada kolom E
C34: Jaminan Penawaran | D34: 0 | E34: =D34*$E$37 -> 0 | F34: * cek dan sesuaikan pengenaan % terhadap revenue / isi nilai manual pada kolom E
C35: Jaminan Pelaksanaan | D35: 0 | E35: =D35*$E$37 -> 0 | F35: * cek dan sesuaikan pengenaan % terhadap revenue / isi nilai manual pada kolom E
C36: Jaminan Pemeliharaan | D36: 0 | E36: =D36*$E$37 -> 0 | F36: * cek dan sesuaikan pengenaan % terhadap revenue / isi nilai manual pada kolom E
C37: REVENUE STREAM / CASH IN | E37: =SUM(E38:E39) -> 29431250 | G37: 29431250
C38: Jasa Pelaksanaan konstruksi | E38: =E24 -> 21982187
C39: Management Fee GSD | D39: 0.33886816 | E39: =D39*SUM(E38) -> 7449063.3 | F39: *terhadap nilai mitra
C40: PERPAJAKAN
C41: PPh | E41: =D68*-1 -> 779928.12
...

Sheet BBM Gombel
C2: TABEL PROFITABILITY PROJECT | G2: KESIMPULAN ANALISIS KELAYAKAN PROJECT
C3: INFORMASI PROJECT | G3: =E6 -> Pekerjaan Pengadaan BBM TTC Gombel
C4: Nama Pelanggan | E4: Telkomsel | G4: =E4 -> Telkomsel
C5: Kategori Project | E5: PS | G5: REVENUE | I5: =IF(E37=D55,E37,"perhitungan salah, CEK KEMBALI CASH FLOW DAN BLOCK REVENUE STREAM") -> 58862000 | J5: =I5=E37 -> TRUE
C6: Nama Project | E6: Pekerjaan Pengadaan BBM TTC Gombel | G6: TOTAL BEBAN/CASH OUT | I6: =IF(E23=D58*-1,E23,"perhitungan salah, CEK KEMBALI CASH FLOW DAN BLOCKCOST STRUCTURE") -> 36400000 | J6: =I6=E23 -> TRUE
C7: Lokasi Project | E7: Kupang | G7: GROSS MARGIN | H7: =I7/I5 -> 0.38160443 | I7: =I5-I6 -> 22462000 | J7: =I7=D67 -> TRUE
C8: Estimasi mulai pekerjaan (MM/YY) | E8: 46259 | G8: Total Pajak PPH | I8: =E41 -> 1559843 | J8: =I8=E41 -> TRUE
A9: =IF(E9="",0,1) -> 1 | C9: Durasi Project (bulan) | E9: 1 | G9: GROSS MARGIN + PPH | H9: =I9/I5 -> 0.35510443 | I9: =I7-I8 -> 20902157
A10: =IF(E10="",0,1) -> 1 | C10: Durasi Retensi (bulan) | E10: 0 | G10: Provisi | I10: =D76*-1 -> 9712.23 | J10: =I10=E45 -> TRUE
C11: Pengawasan Konstruksi Sendiri / Menggunakan MK ? | E11: Sendiri ( by GSD ) | F11: *pilihan | G11: Bunga Pinjaman | I11: =D77*-1 -> 8813.8487 | J11: =I11=E46 -> TRUE
C12: Tipe Bagunan | D12: {=IF(E37<='[128]Tabel PUPR'!A15,'[128]Tabel PUPR'!B15,IF(E37<='[128]Tabel PUPR'!A16,'[128]Tabel PUPR'!B16,IF(E37<='[128]Tabel PUPR'!A17,'[128]Tabel PUPR'!B17,IF(E37<='[128]Tabel PUPR'!A18,'[128]Tabel PUPR'!B18,IF(E37<='[128]Tabel PUPR'!A19,'[128]Tabel PUPR'!B19,IF(E37<='[128]Tabel PUPR'!A20,'[128]Tabel PUPR'!B20,IF(E37<='[128]Tabel PUPR'!A21,'[128]Tabel PUPR'!B21,IF(E37<='[128]Tabel PUPR'!A22,'[128]Tabel PUPR'!B22,IF(E37<='[128]Tabel PUPR'!A23,'[128]Tabel PUPR'!B23,IF(E37<='[128]Tabel PUPR'!A24,'[128]Tabel PUPR'!B24,IF(E37<='[128]Tabel PUPR'!A25,k,k)))))))))))} -> a | E12: Sederhana ( < 2 lantai) | F12: *pilihan | G12: NET INCOME | H12: =I12/I5 -> 0.35478969 | I12: =I9-SUM(I10:I11) -> 20883631
C13: TOP Pembayaran Kepada Mitra | E13: setelah BAST | G13: Kredit PPN | I13: =-D72 -> 2470820
C14: TOP Pembayaran Pelanggan | E14: setelah BAST | G14: NET CASH FLOW | H14: =IF(I14>0,"Cashflow Positif","Cashflow Negatif") -> Cashflow Positif | I14: =I12-I13 -> 18412811 | K14: CATATAN:
C15: ASUMSI-ASUMSI | G15: CF selama kontrak | H15: =COUNTIF(E79:Q79,"<"&0) -> 0 | I15: =IF(H15>0,"Terdapat CF Negatif","All CF Positif") -> All CF Positif
A16: =IF(E10=[129]key!A3,1,0) -> 0 | C16: Suku Bunga per tahun | E16: 0.1089 | G16: KESIMPULAN | H16: =IF(H12>0%,IF(H15=0,IF(H12>10.89%,"Layak dengan Net Income sebesar",IF(I5>1000000000,IF(H12>10.89%,"Tidak Layak dengan Net income dibawah treshold ",IF(H12>0%,"Tidak Layak dengan Net income dibawah treshold","Tidak Layak dengan Net income dibawah treshold")),"Tidak Layak dengan Net income dibawah treshold")),"Tidak Layak dengan Net Income sebesar"),"Tidak Layak dengan Net income dibawah treshold") -> Layak dengan Net Income sebesar | K16: * JIKA TERDAPAT CF NEGATIF :
C17: Suku Bunga per bulan | E17: =E16/12 -> 0.009075 | H17: =H12 -> 0.35478969 | K17: 1. adjust nilai pinjaman hingga CF positif
C18: Pemodalan: Loan | E18: 1 | G18: REVENUE INCL PPN | H18: 11/12*12% | I18: =I5+D70 -> 65336820 | K18: 2. Adjust asumsi pembayaran mitra / customer, namun harus sesuai dengan
C19: Provisi | E19: 0.01 | G19: Notes lain-lain: | K19: kondisi aktual / konfirmasi dengan pihak OM
C20: PPN | E20: 0.12 | G20: =C24 -> Biaya Mitra Pelaksana (Exclude PPN) | I20: =E24 -> 36400000
C21: PPH pasal 23 | E21: 0.0265 | G21: =C31 -> BOP Project | I21: =E31 -> 0
C22: Periode Pinjaman (Bulan) | E22: =E9 -> 1 | G22: =C39 -> Management Fee GSD | I22: =E39 -> 22462000
C23: COST STRUCTURE / CASH OUT | E23: =SUM(E24:E31) -> 36400000
C24: Biaya Mitra Pelaksana (Exclude PPN) | E24: =COGS!H10 -> 36400000
C25: BEBAN LAINNYA | E25: 0
C26: Fee Fasilitas Jaminan | F26: * Minimal 500rb dengan catatan apabila contohnya: 1. Nilai Proyek 10M 2. Jangka waktu kerjasama adalah 3 bulan 3. Nilai Jaminan Dipersyaratkan 15% Maka Cost untuk fee: =(((0.5%/12)x3)x(15%x10M)
C27: Admin Fasilitas Jaminan | F27: * Apabila ada jaminan, biaya admin Rp 250.000,-
C28: Construction Assurance Risk ( CAR) | E28: 0
C29: Iuran Jasa Konstruksi | E29: 0
C30: Biaya Pengawasan | D30: =IF(E11='[128]Tabel PUPR'!D4,0%,VLOOKUP([128]Profitability!D12,'[128]Tabel PUPR'!B15:E25,IF([128]Profitability!E12='[128]Tabel PUPR'!A8,2,IF([128]Profitability!D12='[128]Tabel PUPR'!A9,3,4)))) -> 0 | E30: =D30*$E$24 -> 0 | F30: Berdasarkan PUPR : | G30: 0
C31: BOP Project | D31: =G31 -> 0 | E31: =D31*$E$24 -> 0 | F31: Berdasarkan PUPR : | G31: 0 | H31: *% bisa disesuaikan dengan asumsi sendiri pada kolom D31
C32: JAMINAN - JAMINAN | E32: =SUM(E33:E36) -> 0
C33: Jaminan Uang muka | D33: 0 | E33: =D33*$E$37 -> 0 | F33: * cek dan sesuaikan pengenaan % terhadap revenue / isi nilai manual pada kolom E
C34: Jaminan Penawaran | D34: 0 | E34: =D34*$E$37 -> 0 | F34: * cek dan sesuaikan pengenaan % terhadap revenue / isi nilai manual pada kolom E
C35: Jaminan Pelaksanaan | D35: 0 | E35: =D35*$E$37 -> 0 | F35: * cek dan sesuaikan pengenaan % terhadap revenue / isi nilai manual pada kolom E
C36: Jaminan Pemeliharaan | D36: 0 | E36: =D36*$E$37 -> 0 | F36: * cek dan sesuaikan pengenaan % terhadap revenue / isi nilai manual pada kolom E
C37: REVENUE STREAM / CASH IN | E37: =SUM(E38:E39) -> 58862000 | G37: 58862000
C38: Jasa Pelaksanaan konstruksi | E38: =E24 -> 36400000
C39: Management Fee GSD | D39: 0.61708791 | E39: =D39*SUM(E38) -> 22462000 | F39: *terhadap nilai mitra
C40: PERPAJAKAN
C41: PPh | E41: =D68*-1 -> 1559843
...

Sheet Profitability 5 lokasi
C2: TABEL PROFITABILITY PROJECT | G2: KESIMPULAN ANALISIS KELAYAKAN PROJECT
C3: INFORMASI PROJECT | G3: =E6 -> Pekerjaan Pengadaan BBM Telkomsel 5 Lokasi
C4: Nama Pelanggan | E4: Telkomsel | G4: =E4 -> Telkomsel
C5: Kategori Project | E5: PS | G5: REVENUE | I5: =IF(E37=D55,E37,"perhitungan salah, CEK KEMBALI CASH FLOW DAN BLOCK REVENUE STREAM") -> 279594750 | J5: =I5=E37 -> TRUE
C6: Nama Project | E6: Pekerjaan Pengadaan BBM Telkomsel 5 Lokasi | G6: TOTAL BEBAN/CASH OUT | I6: =IF(E23=D58*-1,E23,"perhitungan salah, CEK KEMBALI CASH FLOW DAN BLOCKCOST STRUCTURE") -> 2.039678e+08 | J6: =I6=E23 -> TRUE
C7: Lokasi Project | E7: Telkomsel 5 Lokasi | G7: GROSS MARGIN | H7: =I7/I5 -> 0.27048774 | I7: =I5-I6 -> 75626951 | J7: =I7=D67 -> TRUE
C8: Estimasi mulai pekerjaan (MM/YY) | E8: 46259 | G8: Total Pajak PPH | I8: =E41 -> 7409260.9 | J8: =I8=E41 -> TRUE
A9: =IF(E9="",0,1) -> 1 | C9: Durasi Project (bulan) | E9: 1 | G9: GROSS MARGIN + PPH | H9: =I9/I5 -> 0.24398774 | I9: =I7-I8 -> 68217690 | J9: =I9=D73 -> TRUE
A10: =IF(E10="",0,1) -> 1 | C10: Durasi Retensi (bulan) | E10: 0 | G10: Provisi | I10: =D76*-1 -> 33654.687 | J10: =I10=E45 -> TRUE
C11: Pengawasan Konstruksi Sendiri / Menggunakan MK ? | E11: Sendiri ( by GSD ) | F11: *pilihan | G11: Bunga Pinjaman | I11: =D77*-1 -> 30541.628 | J11: =I11=E46 -> TRUE
C12: Tipe Bagunan | D12: {=IF(E37<='[128]Tabel PUPR'!A15,'[128]Tabel PUPR'!B15,IF(E37<='[128]Tabel PUPR'!A16,'[128]Tabel PUPR'!B16,IF(E37<='[128]Tabel PUPR'!A17,'[128]Tabel PUPR'!B17,IF(E37<='[128]Tabel PUPR'!A18,'[128]Tabel PUPR'!B18,IF(E37<='[128]Tabel PUPR'!A19,'[128]Tabel PUPR'!B19,IF(E37<='[128]Tabel PUPR'!A20,'[128]Tabel PUPR'!B20,IF(E37<='[128]Tabel PUPR'!A21,'[128]Tabel PUPR'!B21,IF(E37<='[128]Tabel PUPR'!A22,'[128]Tabel PUPR'!B22,IF(E37<='[128]Tabel PUPR'!A23,'[128]Tabel PUPR'!B23,IF(E37<='[128]Tabel PUPR'!A24,'[128]Tabel PUPR'!B24,IF(E37<='[128]Tabel PUPR'!A25,k,k)))))))))))} -> b | E12: Sederhana ( < 2 lantai) | F12: *pilihan | G12: NET INCOME | H12: =I12/I5 -> 0.24375813 | I12: =I9-SUM(I10:I11) -> 68153493 | J12: =I12=F79 -> TRUE
C13: TOP Pembayaran Kepada Mitra | E13: setelah BAST | G13: Kredit PPN | I13: =-D72 -> 8318964.6
C14: TOP Pembayaran Pelanggan | E14: setelah BAST | G14: NET CASH FLOW | H14: =IF(I14>0,"Cashflow Positif","Cashflow Negatif") -> Cashflow Positif | I14: =I12-I13 -> 59834529 | N14: CATATAN:
C15: ASUMSI-ASUMSI | G15: CF selama kontrak | H15: =COUNTIF(E79:Q79,"<"&0) -> 0 | I15: =IF(H15>0,"Terdapat CF Negatif","All CF Positif") -> All CF Positif
A16: =IF(E10=[129]key!A3,1,0) -> 0 | C16: Suku Bunga per tahun | E16: 0.1089 | G16: KESIMPULAN | H16: =IF(H12>0%,IF(H15=0,IF(H12>10.89%,"Layak dengan Net Income sebesar",IF(I5>1000000000,IF(H12>10.89%,"Tidak Layak dengan Net income dibawah treshold ",IF(H12>0%,"Tidak Layak dengan Net income dibawah treshold","Tidak Layak dengan Net income dibawah treshold")),"Tidak Layak dengan Net income dibawah treshold")),"Tidak Layak dengan Net Income sebesar"),"Tidak Layak dengan Net income dibawah treshold") -> Layak dengan Net Income sebesar | N16: * JIKA TERDAPAT CF NEGATIF :
C17: Suku Bunga per bulan | E17: =E16/12 -> 0.009075 | H17: =H12 -> 0.24375813 | N17: 1. adjust nilai pinjaman hingga CF positif
C18: Pemodalan: Loan | E18: 1 | G18: REVENUE INCL PPN | H18: 11/12*12% | I18: =I5+D70 -> 3.1035017e+08 | N18: 2. Adjust asumsi pembayaran mitra / customer, namun harus sesuai dengan
C19: Provisi | E19: 0.01 | G19: Notes lain-lain: | N19: kondisi aktual / konfirmasi dengan pihak OM
C20: PPN | E20: 0.12 | G20: =C24 -> Biaya Mitra Pelaksana (Exclude PPN) | I20: =E24 -> 2.039678e+08
C21: PPH pasal 23 | E21: 0.0265 | G21: =C31 -> BOP Project | I21: =E31 -> 0
C22: Periode Pinjaman (Bulan) | E22: =E9 -> 1 | G22: =C39 -> Management Fee GSD | I22: =E39 -> 75626951
C23: COST STRUCTURE / CASH OUT | E23: =SUM(E24:E31) -> 2.039678e+08
C24: Biaya Mitra Pelaksana (Exclude PPN) | E24: =+COGS!H12 -> 2.039678e+08
C25: BEBAN LAINNYA | E25: 0
C26: Fee Fasilitas Jaminan | F26: * Minimal 500rb dengan catatan apabila contohnya: 1. Nilai Proyek 10M 2. Jangka waktu kerjasama adalah 3 bulan 3. Nilai Jaminan Dipersyaratkan 15% Maka Cost untuk fee: =(((0.5%/12)x3)x(15%x10M)
C27: Admin Fasilitas Jaminan | F27: * Apabila ada jaminan, biaya admin Rp 250.000,-
C28: Construction Assurance Risk ( CAR) | E28: 0
C29: Iuran Jasa Konstruksi | E29: 0
C30: Biaya Pengawasan | D30: =IF(E11='[128]Tabel PUPR'!D4,0%,VLOOKUP([128]Profitability!D12,'[128]Tabel PUPR'!B15:E25,IF([128]Profitability!E12='[128]Tabel PUPR'!A8,2,IF([128]Profitability!D12='[128]Tabel PUPR'!A9,3,4)))) -> 0 | E30: =D30*$E$24 -> 0 | F30: Berdasarkan PUPR : | G30: 0
C31: BOP Project | D31: =G31 -> 0 | E31: =D31*$E$24 -> 0 | F31: Berdasarkan PUPR : | G31: 0 | H31: *% bisa disesuaikan dengan asumsi sendiri pada kolom D31
C32: JAMINAN - JAMINAN | E32: =SUM(E33:E36) -> 0
C33: Jaminan Uang muka | D33: 0 | E33: =D33*$E$37 -> 0 | F33: * cek dan sesuaikan pengenaan % terhadap revenue / isi nilai manual pada kolom E
C34: Jaminan Penawaran | D34: 0 | E34: =D34*$E$37 -> 0 | F34: * cek dan sesuaikan pengenaan % terhadap revenue / isi nilai manual pada kolom E
C35: Jaminan Pelaksanaan | D35: 0 | E35: =D35*$E$37 -> 0 | F35: * cek dan sesuaikan pengenaan % terhadap revenue / isi nilai manual pada kolom E
C36: Jaminan Pemeliharaan | D36: 0 | E36: =D36*$E$37 -> 0 | F36: * cek dan sesuaikan pengenaan % terhadap revenue / isi nilai manual pada kolom E
C37: REVENUE STREAM / CASH IN | E37: =SUM(E38:E39) -> 279594750 | G37: 279594750
C38: Jasa Pelaksanaan konstruksi | E38: =E24 -> 2.039678e+08
C39: Management Fee GSD | D39: 0.37077887 | E39: =D39*SUM(E38) -> 75626951 | F39: *terhadap nilai mitra
C40: PERPAJAKAN
C41: PPh | E41: =D68*-1 -> 7409260.9
...

Sheet COGS
B2: RINCIAN KEBUTUHAN BBM TELKOMSEL 5 LOKASI | P2: Budget Telkomsel
F3: BEBAN | I3: BUDGET TELKOMSEL
B4: NO | C4: LOKASI | D4: SATUAN | E4: QTY | F4: HARGA | G4: HUMLAH | H4: TOTAL | I4: BBM/ LTR | J4: FEE BBM/ LTR | K4: PBBKB 7.5% | L4: SUB TOTAL/ LTR | M4: TOTAL/ LOKASI | N4: Margin Gross
B6: 1 | C6: STO Maumere | D6: Liter | E6: 1500 | F6: 21982 | G6: =F6*E6 -> 32973000 | H6: =G6 -> 32973000 | I6: 26000 | J6: 1500 | K6: 1931 | L6: =I6+J6+K6 -> 29431 | M6: =E6*L6 -> 44146500 | N6: =M6-H6 -> 11173500
B7: =B6+1 -> 2 | C7: HR Muhammad | D7: Liter | E7: 1000 | F7: =25000/1.11 -> 22522.523 | G7: =F7*E7 -> 22522523 | H7: =G7 -> 22522523 | I7: 26000 | J7: 1500 | K7: 1931 | L7: =I7+J7+K7 -> 29431 | M7: =E7*L7 -> 29431000 | N7: =M7-H7 -> 6908477.5
B8: =B7+1 -> 3 | C8: TTC Gayungan | D8: Liter | E8: 4000 | F8: =F7 -> 22522.523 | G8: =F8*E8 -> 90090090 | H8: =G8 -> 90090090 | I8: 26000 | J8: 1500 | K8: 1931 | L8: =I8+J8+K8 -> 29431 | M8: =E8*L8 -> 117724000 | N8: =M8-H8 -> 27633910
B9: =B8+1 -> 4 | C9: STO Palapa Kupang | D9: Liter | E9: 1000.0085 | F9: =F6 -> 21982 | G9: =F9*E9 -> 21982187 | H9: =G9 -> 21982187 | I9: 26000 | J9: 1500 | K9: 1931 | L9: =I9+J9+K9 -> 29431 | M9: =E9*L9 -> 29431250 | N9: =M9-H9 -> 7449063.3
B10: =B9+1 -> 5 | C10: TTC Gombel | D10: Liter | E10: 2000 | F10: 18200 | G10: =F10*E10 -> 36400000 | H10: =G10 -> 36400000 | I10: 26000 | J10: 1500 | K10: 1931 | L10: =I10+J10+K10 -> 29431 | M10: =E10*L10 -> 58862000 | N10: =M10-H10 -> 22462000
C12: TOTAL | H12: =SUM(H6:H11) -> 2.039678e+08 | M12: =SUM(M6:M11) -> 279594750 | N12: =SUM(N6:N11) -> 75626951
L13: margin | M13: =M12-H12 -> 75626951
L14: % | M14: =M13/H12 -> 0.37077887
M16: 0.37077887
P20: BBM NUSRA | R20: 19 Agustus 2026
P64: BBM SURABAYA
P97: BBM GOMBEL | R97: 20 Agustus 2026

Sheet Tabel PUPR
A1: Suplier back to back | D1: Pengawasan Project
A3: YA | D3: Menggunakan MK
A4: TIDAK | D4: Sendiri ( by GSD )
A6: Tipe Bagunan
A8: Sederhana ( < 2 lantai)
A9: Tidak Sederhana (> 2 lantai)
A10: Kriteria Khusus ( Daerah sulit / neocentrix)
A12: Pengawasan
A13: Nilai project | C13: Sederhana | D13: Tidak Sederhana | E13: Klasifikasi Khusus
A14: kecil sama dari
A15: 250000000 | B15: a | C15: 0.1059 | D15: 0.2108 | E15: 0.1574
A16: 500000000 | B16: b | C16: 0.0915 | D16: 0.182 | E16: 0.1323
A17: 1000000000 | B17: c | C17: 0.0772 | D17: 0.1537 | E17: 0.1129
A18: 2500000000 | B18: d | C18: 0.0647 | D18: 0.1288 | E18: 0.0964
A19: 5000000000 | B19: e | C19: 0.0541 | D19: 0.1076 | E19: 0.0871
A20: 10000000000 | B20: f | C20: 0.0449 | D20: 0.0762 | E20: 0.0756
A21: 25000000000 | B21: g | C21: 0.0403 | D21: 0.0513 | E21: 0.0682
A22: 50000000000 | B22: h | C22: 0.0363 | D22: 0.035 | E22: 0.046
A23: 100000000000 | B23: i | C23: 0.0248 | D23: 0.0239 | E23: 0.0314
A24: 250000000000 | B24: j | C24: 0.0159 | D24: 0.015 | E24: 0.029
A25: 500000000000 | B25: k | C25: 0.0149 | D25: 0.011 | E25: 0.0273
A28: BOP (Pengelolaan Kegiatan)
A29: Nilai project | C29: Sederhana | D29: Tidak Sederhana | E29: Klasifikasi Khusus
A30: kecil sama dari
A31: 250000000 | B31: a | C31: 0.14 | D31: 0.16 | E31: 0.16
A32: 500000000 | B32: b | C32: 0.1 | D32: 0.1125 | E32: 0.1125
A33: 1000000000 | B33: c | C33: 0.0675 | D33: 0.0775 | E33: 0.0775
A34: 2500000000 | B34: d | C34: 0.042 | D34: 0.051 | E34: 0.051
A35: 5000000000 | B35: e | C35: 0.0285 | D35: 0.0336 | E35: 0.0335
A36: 10000000000 | B36: f | C36: 0.019 | D36: 0.0224 | E36: 0.0222
A37: 25000000000 | B37: g | C37: 0.012 | D37: 0.0142 | E37: 0.0142
A38: 50000000000 | B38: h | C38: 0.008 | D38: 0.0095 | E38: 0.0095
A39: 100000000000 | B39: i | C39: 0.0054 | D39: 0.0064 | E39: 0.0064
A40: 250000000000 | B40: j | C40: 0.0036 | D40: 0.004 | E40: 0.0041
A41: 500000000000 | B41: k | C41: 0.0025 | D41: 0.0028 | E41: 0.0028

Sheet SPH
B2: RINCIAN LAMPIRAN HARGA BBM TELKOMSEL | G2: 1.2 | Q2: Budget Telkomsel
G3: BEBAN | J3: REVENUE
B4: NO | C4: LOKASI | D4: SATUAN | E4: QTY | F4: HARGA | G4: HARGA | H4: SUBTOTAL | I4: TOTAL | J4: BBM/ LTR | K4: FEE BBM/ LTR | L4: PBBKB 7.5% | M4: SUB TOTAL/ LTR | N4: TOTAL/ LOKASI | O4: Margin Gross
B6: 1 | C6: STO Maumere | D6: Liter | E6: 1500 | F6: 21982 | G6: =G2*M6 -> 35317.2 | H6: =G6*E6 -> 52975800 | I6: =H6 -> 52975800 | J6: 26000 | K6: 1500 | L6: 1931 | M6: =J6+K6+L6 -> 29431 | N6: =E6*M6 -> 44146500 | O6: =N6-I6 -> -8829300
B7: =B6+1 -> 2 | C7: HR Muhammad | D7: Liter | E7: 1000 | F7: =25000/1.11 -> 22522.523 | G7: =G6 -> 35317.2 | H7: =G7*E7 -> 35317200 | I7: =H7 -> 35317200 | J7: 26000 | K7: 1500 | L7: 1931 | M7: =J7+K7+L7 -> 29431 | N7: =E7*M7 -> 29431000 | O7: =N7-I7 -> -5886200
B8: =B7+1 -> 3 | C8: TTC Gayungan | D8: Liter | E8: 4000 | F8: =F7 -> 22522.523 | G8: =G7 -> 35317.2 | H8: =G8*E8 -> 141268800 | I8: =H8 -> 141268800 | J8: 26000 | K8: 1500 | L8: 1931 | M8: =J8+K8+L8 -> 29431 | N8: =E8*M8 -> 117724000 | O8: =N8-I8 -> -23544800
B9: =B8+1 -> 4 | C9: STO Palapa Kupang | D9: Liter | E9: 1000.0085 | F9: =F6 -> 21982 | G9: =G8 -> 35317.2 | H9: =G9*E9 -> 35317500 | I9: =H9 -> 35317500 | J9: 26000 | K9: 1500 | L9: 1931 | M9: =J9+K9+L9 -> 29431 | N9: =E9*M9 -> 29431250 | O9: =N9-I9 -> -5886250
B10: =B9+1 -> 5 | C10: TTC Gombel | D10: Liter | E10: 2000 | F10: 18200 | G10: =G9 -> 35317.2 | H10: =G10*E10 -> 70634400 | I10: =H10 -> 70634400 | J10: 26000 | K10: 1500 | L10: 1931 | M10: =J10+K10+L10 -> 29431 | N10: =E10*M10 -> 58862000 | O10: =N10-I10 -> -11772400
C12: TOTAL | H12: =SUM(H6:H11) -> 335513700 | I12: =SUM(I6:I11) -> 335513700 | N12: =SUM(N6:N11) -> 279594750 | O12: =SUM(O6:O11) -> -55918950
M13: margin | N13: =N12-I12 -> -55918950
M14: % | N14: =N13/I12 -> -0.16666667
N16: 0.37077887
Q20: BBM NUSRA | S20: 19 Agustus 2026
G27: Simulasi perhitungan penawaran mitra
H28: DPP | I28: PBBKB | J28: Biaya Ongkir | K28: Total
G29: Telkomsel | H29: 26000 | I29: =H29*7.5% -> 1950 | J29: 1500 | K29: =SUM(H29:J29) -> 29450
G30: Nusra | H30: 28000 | I30: =H30*7.5% -> 2100 | J30: 1000 | K30: =SUM(H30:J30) -> 31100
G31: Jateng-Jatim | H31: 27600 | I31: =H31*7.5% -> 2070 | J31: 500 | K31: =SUM(H31:J31) -> 30170
G32: SPH | H32: 35317 | K32: =SUM(H32:J32) -> 35317
G36: Harga DPP | H36: 27600
G37: *) Harga belum termasuk Pajak PBBKB, Biaya Ongkir dan Pajak-pajak yang berlaku
Q64: BBM SURABAYA
Q97: BBM GOMBEL | S97: 20 Agustus 2026
