Workbook
Name _________lk05: [1]analisa!$I$42
Name ________lk05: [1]analisa!$I$42
Name _______lk05: [1]analisa!$I$42
Name ______lk05: [1]analisa!$I$42
Name _____EEE07: '[2]ANALISA ALAT'!$AW$15
Name _____EEE30: '[2]ANALISA ALAT'!$AW$38
Name _____EEE31: '[2]ANALISA ALAT'!$AW$39
Name _____lk05: [1]analisa!$I$42
Name _____MMM04: [3]UPAH!$F$57
Name _____MMM09: [2]UPAH!$F$59
Name _____MMM10: [3]UPAH!$F$63
Name _____MMM11: [3]UPAH!$F$64
Name _____MMM16: [2]UPAH!$F$68
Name _____MMM19: [3]UPAH!$F$78
Name _____MMM37: [2]UPAH!$F$95
Name _____MMM39: [3]UPAH!$F$99
Name ____lk05: [1]analisa!$I$42
Name ____xlnm._FilterDatabase: NA()
Name ___lk05: [1]analisa!$I$42
Name ___xlnm._FilterDatabase_1: NA()
Name __1A: NA()
Name __1A_11: NA()
Name __1A_12: NA()
Name __1A_13: NA()
Name __1A_14: NA()
Name __1A_15: NA()
Name __1A_16: NA()
Name __1A_17: NA()
Name __1A_18: NA()
Name __1A_3: NA()
Name __1A_4: NA()
Name __1A_5: NA()
Name __1A_6: NA()
Name __1A_7: NA()
Name __BET135: [6]anlisa!$P$143
Name __DIN12: [6]anlisa!$P$85
Name __DIN15: [6]anlisa!$P$95
Name __lk05: [1]analisa!$I$42
Name __LT4040: [6]anlisa!$P$540
Name __MDE01: [7]an.alat!$BO$28
Name __MDE02: [7]an.alat!$BO$49
Name __MDE03: [7]an.alat!$BO$66
Name __MDE04: [7]an.alat!$BO$86
Name __MDE05: [7]an.alat!$BO$106
Name __MDE06: [7]an.alat!$BO$124
Name __MDE07: [7]an.alat!$BO$144
Name __MDE08: [7]an.alat!$BO$164
Name __MDE09: [7]an.alat!$BO$183
Name __MDE10: [7]an.alat!$BO$203
Name __MDE11: [7]an.alat!$BO$223
Name __MDE12: [7]an.alat!$BO$241
Name __MDE13: [7]an.alat!$BO$261
Name __MDE14: [7]an.alat!$BO$281
Name __MDE15: [7]an.alat!$BO$299
Name __MDE16: [7]an.alat!$BO$319
Name __MDE17: [7]an.alat!$BO$339
Name __MDE18: [7]an.alat!$BO$357
Name __MDE19: [7]an.alat!$BO$377
Name __MDE20: [7]an.alat!$BO$397
Name __MDE21: [7]an.alat!$BO$415

Sheet Cover
E6: PEKERJAAN
C7: PEMBUATAN INTERIOR KANTOR REGIONAL III PT ASDP INDONESIA FERRY
E8: PAKUWON TOWER LANTAI 22
E9: SURABAYA
E11: LAPORAN MINGGUAN
E12: (WEEKLY REPORT)
J21: Minggu | K21: Start | L21: End | M21: Start | N21: End
J22: 1 | K22: 46226 | L22: =K22+3 -> 46229 | M22: =K22 -> 46226 | N22: =L22 -> 46229
J23: =J22+1 -> 2 | K23: =L22+1 -> 46230 | L23: =K23+6 -> 46236 | M23: =K23 -> 46230 | N23: =L23 -> 46236
J24: =J23+1 -> 3 | K24: =L23+1 -> 46237 | L24: =K24+6 -> 46243 | M24: =K24 -> 46237 | N24: =L24 -> 46243
J25: =J24+1 -> 4 | K25: =L24+1 -> 46244 | L25: =K25+6 -> 46250 | M25: =K25 -> 46244 | N25: =L25 -> 46250
J26: =J25+1 -> 5 | K26: =L25+1 -> 46251 | L26: =K26+6 -> 46257 | M26: =K26 -> 46251 | N26: =L26 -> 46257
J27: =J26+1 -> 6 | K27: =L26+1 -> 46258 | L27: =K27+6 -> 46264 | M27: =K27 -> 46258 | N27: =L27 -> 46264
J28: =J27+1 -> 7 | K28: =L27+1 -> 46265 | L28: =K28+6 -> 46271 | M28: =K28 -> 46265 | N28: =L28 -> 46271
J29: =J28+1 -> 8 | K29: =L28+1 -> 46272 | L29: =K29+6 -> 46278 | M29: =K29 -> 46272 | N29: =L29 -> 46278
J30: =J29+1 -> 9 | K30: =L29+1 -> 46279 | L30: =K30+6 -> 46285 | M30: =K30 -> 46279 | N30: =L30 -> 46285
E32: PERIODE :
E33: MINGGU KE
E34: 5
D35: =VLOOKUP(E34,mingguanptasdp,2) -> 46251 | E35: hingga | F35: =VLOOKUP(E34,mingguanptasdp,3) -> 46257
E41: =K22 -> 46226

Sheet Rekap_Prog
B1: PROGRES PEKERJAAN
B2: =Cover!C7 -> PEMBUATAN INTERIOR KANTOR REGIONAL III PT ASDP INDONESIA FERRY
B3: Pakuwon Tower Lantai 22, Jl. Embong Malang No. 32-36, Kedungdoro, Kec. Tegalsari | I3: Week : | J3: 1 | O3: Week : | P3: =J3+1 -> 2 | U3: Week : | V3: =P3+1 -> 3 | AA3: Week : | AB3: =V3+1 -> 4 | AG3: Week : | AH3: =AB3+1 -> 5 | AM3: Week : | AN3: =AH3+1 -> 6 | AS3: Week : | AT3: =AN3+1 -> 7 | AY3: Week : | AZ3: =AT3+1 -> 8 | BE3: Week : | BF3: =AZ3+1 -> 9
B4: Surabaya | I4: Mulai : | J4: =VLOOKUP(J3,mingguanptasdp,2) -> 46226 | O4: Mulai : | P4: =VLOOKUP(P3,mingguanptasdp,2) -> 46230 | U4: Mulai : | V4: =VLOOKUP(V3,mingguanptasdp,2) -> 46237 | AA4: Mulai : | AB4: =VLOOKUP(AB3,mingguanptasdp,2) -> 46244 | AG4: Mulai : | AH4: =VLOOKUP(AH3,mingguanptasdp,2) -> 46251 | AM4: Mulai : | AN4: =VLOOKUP(AN3,mingguanptasdp,2) -> 46258 | AS4: Mulai : | AT4: =VLOOKUP(AT3,mingguanptasdp,2) -> 46265 | AY4: Mulai : | AZ4: =VLOOKUP(AZ3,mingguanptasdp,2) -> 46272 | BE4: Mulai : | BF4: =VLOOKUP(BF3,mingguanptasdp,2) -> 46279
I5: Hingga : | J5: =VLOOKUP(J3,mingguanptasdp,3) -> 46229 | O5: Hingga : | P5: =VLOOKUP(P3,mingguanptasdp,3) -> 46236 | U5: Hingga : | V5: =VLOOKUP(V3,mingguanptasdp,3) -> 46243 | AA5: Hingga : | AB5: =VLOOKUP(AB3,mingguanptasdp,3) -> 46250 | AG5: Hingga : | AH5: =VLOOKUP(AH3,mingguanptasdp,3) -> 46257 | AM5: Hingga : | AN5: =VLOOKUP(AN3,mingguanptasdp,3) -> 46264 | AS5: Hingga : | AT5: =VLOOKUP(AT3,mingguanptasdp,3) -> 46271 | AY5: Hingga : | AZ5: =VLOOKUP(AZ3,mingguanptasdp,3) -> 46278 | BE5: Hingga : | BF5: =VLOOKUP(BF3,mingguanptasdp,3) -> 46285
B6: NO | C6: ITEM PEKERJAAN | D6: BOBOT | E6: KEMAJUAN PEKERJAAN MINGGUAN | K6: KEMAJUAN PEKERJAAN MINGGUAN | Q6: KEMAJUAN PEKERJAAN MINGGUAN | W6: KEMAJUAN PEKERJAAN MINGGUAN | AC6: KEMAJUAN PEKERJAAN MINGGUAN | AI6: KEMAJUAN PEKERJAAN MINGGUAN | AO6: KEMAJUAN PEKERJAAN MINGGUAN | AU6: KEMAJUAN PEKERJAAN MINGGUAN | BA6: KEMAJUAN PEKERJAAN MINGGUAN
E7: MINGGU LALU | G7: MINGGU INI | I7: S/D MINGGU INI | K7: MINGGU LALU | M7: MINGGU INI | O7: S/D MINGGU INI | Q7: MINGGU LALU | S7: MINGGU INI | U7: S/D MINGGU INI | W7: MINGGU LALU | Y7: MINGGU INI | AA7: S/D MINGGU INI | AC7: MINGGU LALU | AE7: MINGGU INI | AG7: S/D MINGGU INI | AI7: MINGGU LALU | AK7: MINGGU INI | AM7: S/D MINGGU INI | AO7: MINGGU LALU | AQ7: MINGGU INI | AS7: S/D MINGGU INI | AU7: MINGGU LALU | AW7: MINGGU INI | AY7: S/D MINGGU INI | BA7: MINGGU LALU | BC7: MINGGU INI | BE7: S/D MINGGU INI
E8: PRESTASI % | F8: BOBOT % | G8: PRESTASI % | H8: BOBOT % | I8: PRESTASI % | J8: BOBOT % | K8: PRESTASI % | L8: BOBOT % | M8: PRESTASI % | N8: BOBOT % | O8: PRESTASI % | P8: BOBOT % | Q8: PRESTASI % | R8: BOBOT % | S8: PRESTASI % | T8: BOBOT % | U8: PRESTASI % | V8: BOBOT % | W8: PRESTASI % | X8: BOBOT % | Y8: PRESTASI % | Z8: BOBOT % | AA8: PRESTASI % | AB8: BOBOT % | AC8: PRESTASI % | AD8: BOBOT % | AE8: PRESTASI % | AF8: BOBOT % | AG8: PRESTASI % | AH8: BOBOT % | AI8: PRESTASI % | AJ8: BOBOT % | AK8: PRESTASI % | AL8: BOBOT % | AM8: PRESTASI % | AN8: BOBOT % | AO8: PRESTASI % | AP8: BOBOT % | AQ8: PRESTASI % | AR8: BOBOT % | AS8: PRESTASI % | AT8: BOBOT % | AU8: PRESTASI % | AV8: BOBOT % | AW8: PRESTASI % | AX8: BOBOT % | AY8: PRESTASI % | AZ8: BOBOT % | BA8: PRESTASI % | BB8: BOBOT % | BC8: PRESTASI % | BD8: BOBOT % | BE8: PRESTASI % | BF8: BOBOT %
B9: 1 | C9: =B9+1 -> 2 | D9: =C9+1 -> 3 | E9: 4 | F9: =E9+1 -> 5 | G9: =F9+1 -> 6 | H9: =G9+1 -> 7 | I9: =H9+1 -> 8 | J9: =I9+1 -> 9 | K9: 4 | L9: =K9+1 -> 5 | M9: =L9+1 -> 6 | N9: =M9+1 -> 7 | O9: =N9+1 -> 8 | P9: =O9+1 -> 9 | Q9: 4 | R9: =Q9+1 -> 5 | S9: =R9+1 -> 6 | T9: =S9+1 -> 7 | U9: =T9+1 -> 8 | V9: =U9+1 -> 9 | W9: 4 | X9: =W9+1 -> 5 | Y9: =X9+1 -> 6 | Z9: =Y9+1 -> 7 | AA9: =Z9+1 -> 8 | AB9: =AA9+1 -> 9 | AC9: 4 | AD9: =AC9+1 -> 5 | AE9: =AD9+1 -> 6 | AF9: =AE9+1 -> 7 | AG9: =AF9+1 -> 8 | AH9: =AG9+1 -> 9 | AI9: 4 | AJ9: =AI9+1 -> 5 | AK9: =AJ9+1 -> 6 | AL9: =AK9+1 -> 7 | AM9: =AL9+1 -> 8 | AN9: =AM9+1 -> 9 | AO9: 4 | AP9: =AO9+1 -> 5 | AQ9: =AP9+1 -> 6 | AR9: =AQ9+1 -> 7 | AS9: =AR9+1 -> 8 | AT9: =AS9+1 -> 9 | AU9: 4 | AV9: =AU9+1 -> 5 | AW9: =AV9+1 -> 6 | AX9: =AW9+1 -> 7 | AY9: =AX9+1 -> 8 | AZ9: =AY9+1 -> 9 | BA9: 4 | BB9: =BA9+1 -> 5 | BC9: =BB9+1 -> 6 | BD9: =BC9+1 -> 7 | BE9: =BD9+1 -> 8 | BF9: =BE9+1 -> 9
B11: I | C11: PEKERJAAN PERSIAPAN | D11: =SUM(Rincian_Prog!I12:I20) -> 9.3291246 | E11: =F11/$D11 -> 0 | F11: =SUM(Rincian_Prog!K12:K20) -> 0 | G11: =H11/$D11 -> 0 | H11: =SUM(Rincian_Prog!M12:M20) -> 0 | I11: =J11/$D11 -> 0 | J11: =SUM(Rincian_Prog!O12:O20) -> 0 | K11: =L11/$D11 -> 0 | L11: =SUM(Rincian_Prog!Q12:Q20) -> 0 | M11: =N11/$D11 -> 0 | N11: =SUM(Rincian_Prog!S12:S20) -> 0 | O11: =P11/$D11 -> 0 | P11: =SUM(Rincian_Prog!U12:U20) -> 0 | Q11: =R11/$D11 -> 0 | R11: =SUM(Rincian_Prog!W12:W20) -> 0 | S11: =T11/$D11 -> 0.14368853 | T11: =SUM(Rincian_Prog!Y12:Y20) -> 1.3404882 | U11: =V11/$D11 -> 0.14368853 | V11: =SUM(Rincian_Prog!AA12:AA20) -> 1.3404882 | W11: =X11/$D11 -> 0.14368853 | X11: =SUM(Rincian_Prog!AC12:AC20) -> 1.3404882 | Y11: =Z11/$D11 -> 0.78322656 | Z11: =SUM(Rincian_Prog!AE12:AE20) -> 7.3068182 | AA11: =AB11/$D11 -> 0.9269151 | AB11: =SUM(Rincian_Prog!AG12:AG20) -> 8.6473064 | AC11: =AD11/$D11 -> 0.9269151 | AD11: =SUM(Rincian_Prog!AI12:AI20) -> 8.6473064 | AE11: =AF11/$D11 -> 0.024361635 | AF11: =SUM(Rincian_Prog!AK12:AK20) -> 0.22727273 | AG11: =AH11/$D11 -> 0.95127673 | AH11: =SUM(Rincian_Prog!AM12:AM20) -> 8.8745791 | AI11: =AJ11/$D11 -> 0.95127673 | AJ11: =SUM(Rincian_Prog!AO12:AO20) -> 8.8745791 | AK11: =AL11/$D11 -> 0.012180817 | AL11: =SUM(Rincian_Prog!AQ12:AQ20) -> 0.11363636 | AM11: =AN11/$D11 -> 0.96345755 | AN11: =SUM(Rincian_Prog!AS12:AS20) -> 8.9882155 | AO11: =AP11/$D11 -> 0.96345755 | AP11: =SUM(Rincian_Prog!AU12:AU20) -> 8.9882155 | AQ11: =AR11/$D11 -> -0.96345755 | AR11: =SUM(Rincian_Prog!AW12:AW20) -> -8.9882155 | AS11: =AT11/$D11 -> 0 | AT11: =SUM(Rincian_Prog!AY12:AY20) -> 0 | AU11: =AV11/$D11 -> 0 | AV11: =SUM(Rincian_Prog!BA12:BA20) -> 0 | AW11: =AX11/$D11 -> 0 | AX11: =SUM(Rincian_Prog!BC12:BC20) -> 0 | AY11: =AZ11/$D11 -> 0 | AZ11: =SUM(Rincian_Prog!BE12:BE20) -> 0 | BA11: =BB11/$D11 -> 0 | BB11: =SUM(Rincian_Prog!BG12:BG20) -> 0 | BC11: =BD11/$D11 -> 0 | BD11: =SUM(Rincian_Prog!BI12:BI20) -> 0 | BE11: =BF11/$D11 -> 0 | BF11: =SUM(Rincian_Prog!BK12:BK20) -> 0
B13: II | C13: PEKERJAAN FIT OUT INTERIOR DAN ARSITEKTUR
B14: II.A | C14: Pekerjaan Ruang Staff & Resepsionis | D14: =SUM(Rincian_Prog!I27:I55) -> 35.219991 | E14: =F14/$D14 -> 0 | F14: =SUM(Rincian_Prog!K27:K55) -> 0 | G14: =H14/$D14 -> 0 | H14: =SUM(Rincian_Prog!M27:M55) -> 0 | I14: =J14/$D14 -> 0 | J14: =SUM(Rincian_Prog!O27:O55) -> 0 | K14: =L14/$D14 -> 0 | L14: =SUM(Rincian_Prog!Q27:Q55) -> 0 | M14: =N14/$D14 -> 0 | N14: =SUM(Rincian_Prog!S27:S55) -> 0 | O14: =P14/$D14 -> 0 | P14: =SUM(Rincian_Prog!U27:U55) -> 0 | Q14: =R14/$D14 -> 0 | R14: =SUM(Rincian_Prog!W27:W55) -> 0 | S14: =T14/$D14 -> 0.057470669 | T14: =SUM(Rincian_Prog!Y27:Y55) -> 2.0241164 | U14: =V14/$D14 -> 0.057470669 | V14: =SUM(Rincian_Prog!AA27:AA55) -> 2.0241164 | W14: =X14/$D14 -> 0.057470669 | X14: =SUM(Rincian_Prog!AC27:AC55) -> 2.0241164 | Y14: =Z14/$D14 -> 0.18328243 | Z14: =SUM(Rincian_Prog!AE27:AE55) -> 6.4552054 | AA14: =AB14/$D14 -> 0.2407531 | AB14: =SUM(Rincian_Prog!AG27:AG55) -> 8.4793218 | AC14: =AD14/$D14 -> 0.2407531 | AD14: =SUM(Rincian_Prog!AI27:AI55) -> 8.4793218 | AE14: =AF14/$D14 -> 0.094358819 | AF14: =SUM(Rincian_Prog!AK27:AK55) -> 3.3233167 | AG14: =AH14/$D14 -> 0.33511192 | AH14: =SUM(Rincian_Prog!AM27:AM55) -> 11.802639 | AI14: =AJ14/$D14 -> 0.33511192 | AJ14: =SUM(Rincian_Prog!AO27:AO55) -> 11.802639 | AK14: =AL14/$D14 -> 0.13822323 | AL14: =SUM(Rincian_Prog!AQ27:AQ55) -> 4.8682209 | AM14: =AN14/$D14 -> 0.47333515 | AN14: =SUM(Rincian_Prog!AS27:AS55) -> 16.670859 | AO14: =AP14/$D14 -> 0.47333515 | AP14: =SUM(Rincian_Prog!AU27:AU55) -> 16.670859 | AQ14: =AR14/$D14 -> -0.47333515 | AR14: =SUM(Rincian_Prog!AW27:AW55) -> -16.670859 | AS14: =AT14/$D14 -> 0 | AT14: =SUM(Rincian_Prog!AY27:AY55) -> 0 | AU14: =AV14/$D14 -> 0 | AV14: =SUM(Rincian_Prog!BA27:BA55) -> 0 | AW14: =AX14/$D14 -> 0 | AX14: =SUM(Rincian_Prog!BC27:BC55) -> 0 | AY14: =AZ14/$D14 -> 0 | AZ14: =SUM(Rincian_Prog!BE27:BE55) -> 0 | BA14: =BB14/$D14 -> 0 | BB14: =SUM(Rincian_Prog!BG27:BG55) -> 0 | BC14: =BD14/$D14 -> 0 | BD14: =SUM(Rincian_Prog!BI27:BI55) -> 0 | BE14: =BF14/$D14 -> 0 | BF14: =SUM(Rincian_Prog!BK27:BK55) -> 0
B16: II.C | C16: Pekerjaan Ruang VIP | D16: =SUM(Rincian_Prog!I62:I128) -> 21.323992 | E16: =F16/$D16 -> 0 | F16: =SUM(Rincian_Prog!K62:K128) -> 0 | G16: =H16/$D16 -> 0 | H16: =SUM(Rincian_Prog!M62:M128) -> 0 | I16: =J16/$D16 -> 0 | J16: =SUM(Rincian_Prog!O62:O128) -> 0 | K16: =L16/$D16 -> 0 | L16: =SUM(Rincian_Prog!Q62:Q128) -> 0 | M16: =N16/$D16 -> 0 | N16: =SUM(Rincian_Prog!S62:S128) -> 0 | O16: =P16/$D16 -> 0 | P16: =SUM(Rincian_Prog!U62:U128) -> 0 | Q16: =R16/$D16 -> 0 | R16: =SUM(Rincian_Prog!W62:W128) -> 0 | S16: =T16/$D16 -> 0.020495054 | T16: =SUM(Rincian_Prog!Y62:Y128) -> 0.43703636 | U16: =V16/$D16 -> 0.020495054 | V16: =SUM(Rincian_Prog!AA62:AA128) -> 0.43703636 | W16: =X16/$D16 -> 0.020495054 | X16: =SUM(Rincian_Prog!AC62:AC128) -> 0.43703636 | Y16: =Z16/$D16 -> 0.065361744 | Z16: =SUM(Rincian_Prog!AE62:AE128) -> 1.3937733 | AA16: =AB16/$D16 -> 0.085856798 | AB16: =SUM(Rincian_Prog!AG62:AG128) -> 1.8308097 | AC16: =AD16/$D16 -> 0.085856798 | AD16: =SUM(Rincian_Prog!AI62:AI128) -> 1.8308097 | AE16: =AF16/$D16 -> 0.1209599 | AF16: =SUM(Rincian_Prog!AK62:AK128) -> 2.579348 | AG16: =AH16/$D16 -> 0.2068167 | AH16: =SUM(Rincian_Prog!AM62:AM128) -> 4.4101577 | AI16: =AJ16/$D16 -> 0.2068167 | AJ16: =SUM(Rincian_Prog!AO62:AO128) -> 4.4101577 | AK16: =AL16/$D16 -> 0.31661081 | AL16: =SUM(Rincian_Prog!AQ62:AQ128) -> 6.7514066 | AM16: =AN16/$D16 -> 0.52342751 | AN16: =SUM(Rincian_Prog!AS62:AS128) -> 11.161564 | AO16: =AP16/$D16 -> 0.52342751 | AP16: =SUM(Rincian_Prog!AU62:AU128) -> 11.161564 | AQ16: =AR16/$D16 -> -0.52342751 | AR16: =SUM(Rincian_Prog!AW62:AW128) -> -11.161564 | AS16: =AT16/$D16 -> 0 | AT16: =SUM(Rincian_Prog!AY62:AY128) -> 0 | AU16: =AV16/$D16 -> 0 | AV16: =SUM(Rincian_Prog!BA62:BA128) -> 0 | AW16: =AX16/$D16 -> 0 | AX16: =SUM(Rincian_Prog!BC62:BC128) -> 0 | AY16: =AZ16/$D16 -> 0 | AZ16: =SUM(Rincian_Prog!BE62:BE128) -> 0 | BA16: =BB16/$D16 -> 0 | BB16: =SUM(Rincian_Prog!BG62:BG128) -> 0 | BC16: =BD16/$D16 -> 0 | BD16: =SUM(Rincian_Prog!BI62:BI128) -> 0 | BE16: =BF16/$D16 -> 0 | BF16: =SUM(Rincian_Prog!BK62:BK128) -> 0
B18: II.D | C18: Pekerjaan Ruang Executive Director | D18: =SUM(Rincian_Prog!I134:I163) -> 11.097262 | E18: =F18/$D18 -> 0 | F18: =SUM(Rincian_Prog!K134:K163) -> 0 | G18: =H18/$D18 -> 0 | H18: =SUM(Rincian_Prog!M134:M163) -> 0 | I18: =J18/$D18 -> 0 | J18: =SUM(Rincian_Prog!O134:O163) -> 0 | K18: =L18/$D18 -> 0 | L18: =SUM(Rincian_Prog!Q134:Q163) -> 0 | M18: =N18/$D18 -> 0 | N18: =SUM(Rincian_Prog!S134:S163) -> 0 | O18: =P18/$D18 -> 0 | P18: =SUM(Rincian_Prog!U134:U163) -> 0 | Q18: =R18/$D18 -> 0 | R18: =SUM(Rincian_Prog!W134:W163) -> 0 | S18: =T18/$D18 -> 0.022842903 | T18: =SUM(Rincian_Prog!Y134:Y163) -> 0.25349369 | U18: =V18/$D18 -> 0.022842903 | V18: =SUM(Rincian_Prog!AA134:AA163) -> 0.25349369 | W18: =X18/$D18 -> 0.022842903 | X18: =SUM(Rincian_Prog!AC134:AC163) -> 0.25349369 | Y18: =Z18/$D18 -> 0.072849382 | Z18: =SUM(Rincian_Prog!AE134:AE163) -> 0.8084287 | AA18: =AB18/$D18 -> 0.095692285 | AB18: =SUM(Rincian_Prog!AG134:AG163) -> 1.0619224 | AC18: =AD18/$D18 -> 0.095692285 | AD18: =SUM(Rincian_Prog!AI134:AI163) -> 1.0619224 | AE18: =AF18/$D18 -> 0.1293869 | AF18: =SUM(Rincian_Prog!AK134:AK163) -> 1.4358403 | AG18: =AH18/$D18 -> 0.22507918 | AH18: =SUM(Rincian_Prog!AM134:AM163) -> 2.4977627 | AI18: =AJ18/$D18 -> 0.22507918 | AJ18: =SUM(Rincian_Prog!AO134:AO163) -> 2.4977627 | AK18: =AL18/$D18 -> 0.26377745 | AL18: =SUM(Rincian_Prog!AQ134:AQ163) -> 2.9272075 | AM18: =AN18/$D18 -> 0.48885663 | AN18: =SUM(Rincian_Prog!AS134:AS163) -> 5.4249702 | AO18: =AP18/$D18 -> 0.48885663 | AP18: =SUM(Rincian_Prog!AU134:AU163) -> 5.4249702 | AQ18: =AR18/$D18 -> -0.48885663 | AR18: =SUM(Rincian_Prog!AW134:AW163) -> -5.4249702 | AS18: =AT18/$D18 -> 0 | AT18: =SUM(Rincian_Prog!AY134:AY163) -> 0 | AU18: =AV18/$D18 -> 0 | AV18: =SUM(Rincian_Prog!BA134:BA163) -> 0 | AW18: =AX18/$D18 -> 0 | AX18: =SUM(Rincian_Prog!BC134:BC163) -> 0 | AY18: =AZ18/$D18 -> 0 | AZ18: =SUM(Rincian_Prog!BE134:BE163) -> 0 | BA18: =BB18/$D18 -> 0 | BB18: =SUM(Rincian_Prog!BG134:BG163) -> 0 | BC18: =BD18/$D18 -> 0 | BD18: =SUM(Rincian_Prog!BI134:BI163) -> 0 | BE18: =BF18/$D18 -> 0 | BF18: =SUM(Rincian_Prog!BK134:BK163) -> 0
B20: III | C20: PEKERJAAN MEKANIKAL ELEKTRIKAL
B21: III.A | C21: Pekerjaan Elektrikal | D21: =SUM(Rincian_Prog!I171:I191) -> 22.673401 | E21: =F21/$D21 -> 0 | F21: =SUM(Rincian_Prog!K171:K191) -> 0 | G21: =H21/$D21 -> 0 | H21: =SUM(Rincian_Prog!M171:M191) -> 0 | I21: =J21/$D21 -> 0 | J21: =SUM(Rincian_Prog!O171:O191) -> 0 | K21: =L21/$D21 -> 0 | L21: =SUM(Rincian_Prog!Q171:Q191) -> 0 | M21: =N21/$D21 -> 0 | N21: =SUM(Rincian_Prog!S171:S191) -> 0 | O21: =P21/$D21 -> 0 | P21: =SUM(Rincian_Prog!U171:U191) -> 0 | Q21: =R21/$D21 -> 0 | R21: =SUM(Rincian_Prog!W171:W191) -> 0 | S21: =T21/$D21 -> 0 | T21: =SUM(Rincian_Prog!Y171:Y191) -> 0 | U21: =V21/$D21 -> 0 | V21: =SUM(Rincian_Prog!AA171:AA191) -> 0 | W21: =X21/$D21 -> 0 | X21: =SUM(Rincian_Prog!AC171:AC191) -> 0 | Y21: =Z21/$D21 -> 0 | Z21: =SUM(Rincian_Prog!AE171:AE191) -> 0 | AA21: =AB21/$D21 -> 0 | AB21: =SUM(Rincian_Prog!AG171:AG191) -> 0 | AC21: =AD21/$D21 -> 0 | AD21: =SUM(Rincian_Prog!AI171:AI191) -> 0 | AE21: =AF21/$D21 -> 0.20242204 | AF21: =SUM(Rincian_Prog!AK171:AK191) -> 4.589596 | AG21: =AH21/$D21 -> 0.20242204 | AH21: =SUM(Rincian_Prog!AM171:AM191) -> 4.589596 | AI21: =AJ21/$D21 -> 0.20242204 | AJ21: =SUM(Rincian_Prog!AO171:AO191) -> 4.589596 | AK21: =AL21/$D21 -> 0.10878675 | AL21: =SUM(Rincian_Prog!AQ171:AQ191) -> 2.4665657 | AM21: =AN21/$D21 -> 0.31120879 | AN21: =SUM(Rincian_Prog!AS171:AS191) -> 7.0561616 | AO21: =AP21/$D21 -> 0.31120879 | AP21: =SUM(Rincian_Prog!AU171:AU191) -> 7.0561616 | AQ21: =AR21/$D21 -> -0.31120879 | AR21: =SUM(Rincian_Prog!AW171:AW191) -> -7.0561616 | AS21: =AT21/$D21 -> 0 | AT21: =SUM(Rincian_Prog!AY171:AY191) -> 0 | AU21: =AV21/$D21 -> 0 | AV21: =SUM(Rincian_Prog!BA171:BA191) -> 0 | AW21: =AX21/$D21 -> 0 | AX21: =SUM(Rincian_Prog!BC171:BC191) -> 0 | AY21: =AZ21/$D21 -> 0 | AZ21: =SUM(Rincian_Prog!BE171:BE191) -> 0 | BA21: =BB21/$D21 -> 0 | BB21: =SUM(Rincian_Prog!BG171:BG191) -> 0 | BC21: =BD21/$D21 -> 0 | BD21: =SUM(Rincian_Prog!BI171:BI191) -> 0 | BE21: =BF21/$D21 -> 0 | BF21: =SUM(Rincian_Prog!BK171:BK191) -> 0
B23: III.B | C23: Pekerjaan Exhaust Fan | D23: =SUM(Rincian_Prog!I193:I194) -> 0.35622963 | E23: =F23/$D23 -> 0 | F23: =SUM(Rincian_Prog!K193:K194) -> 0 | G23: =H23/$D23 -> 0 | H23: =SUM(Rincian_Prog!M193:M194) -> 0 | I23: =J23/$D23 -> 0 | J23: =SUM(Rincian_Prog!O193:O194) -> 0 | K23: =L23/$D23 -> 0 | L23: =SUM(Rincian_Prog!Q193:Q194) -> 0 | M23: =N23/$D23 -> 0 | N23: =SUM(Rincian_Prog!S193:S194) -> 0 | O23: =P23/$D23 -> 0 | P23: =SUM(Rincian_Prog!U193:U194) -> 0 | Q23: =R23/$D23 -> 0 | R23: =SUM(Rincian_Prog!W193:W194) -> 0 | S23: =T23/$D23 -> 0 | T23: =SUM(Rincian_Prog!Y193:Y194) -> 0 | U23: =V23/$D23 -> 0 | V23: =SUM(Rincian_Prog!AA193:AA194) -> 0 | W23: =X23/$D23 -> 0 | X23: =SUM(Rincian_Prog!AC193:AC194) -> 0 | Y23: =Z23/$D23 -> 0 | Z23: =SUM(Rincian_Prog!AE193:AE194) -> 0 | AA23: =AB23/$D23 -> 0 | AB23: =SUM(Rincian_Prog!AG193:AG194) -> 0 | AC23: =AD23/$D23 -> 0 | AD23: =SUM(Rincian_Prog!AI193:AI194) -> 0 | AE23: =AF23/$D23 -> 0 | AF23: =SUM(Rincian_Prog!AK193:AK194) -> 0 | AG23: =AH23/$D23 -> 0 | AH23: =SUM(Rincian_Prog!AM193:AM194) -> 0 | AI23: =AJ23/$D23 -> 0 | AJ23: =SUM(Rincian_Prog!AO193:AO194) -> 0 | AK23: =AL23/$D23 -> 0 | AL23: =SUM(Rincian_Prog!AQ193:AQ194) -> 0 | AM23: =AN23/$D23 -> 0 | AN23: =SUM(Rincian_Prog!AS193:AS194) -> 0 | AO23: =AP23/$D23 -> 0 | AP23: =SUM(Rincian_Prog!AU193:AU194) -> 0 | AQ23: =AR23/$D23 -> 0 | AR23: =SUM(Rincian_Prog!AW193:AW194) -> 0 | AS23: =AT23/$D23 -> 0 | AT23: =SUM(Rincian_Prog!AY193:AY194) -> 0 | AU23: =AV23/$D23 -> 0 | AV23: =SUM(Rincian_Prog!BA193:BA194) -> 0 | AW23: =AX23/$D23 -> 0 | AX23: =SUM(Rincian_Prog!BC193:BC194) -> 0 | AY23: =AZ23/$D23 -> 0 | AZ23: =SUM(Rincian_Prog!BE193:BE194) -> 0 | BA23: =BB23/$D23 -> 0 | BB23: =SUM(Rincian_Prog!BG193:BG194) -> 0 | BC23: =BD23/$D23 -> 0 | BD23: =SUM(Rincian_Prog!BI193:BI194) -> 0 | BE23: =BF23/$D23 -> 0 | BF23: =SUM(Rincian_Prog!BK193:BK194) -> 0
D25: =SUM(D10:D24) -> 100 | F25: =SUM(F10:F24) -> 0 | H25: =SUM(H10:H24) -> 0 | J25: =SUM(J10:J24) -> 0 | L25: =SUM(L10:L24) -> 0 | N25: =SUM(N10:N24) -> 0 | P25: =SUM(P10:P24) -> 0 | R25: =SUM(R10:R24) -> 0 | T25: =SUM(T10:T24) -> 4.0551347 | V25: =SUM(V10:V24) -> 4.0551347 | X25: =SUM(X10:X24) -> 4.0551347 | Z25: =SUM(Z10:Z24) -> 15.964226 | AB25: =SUM(AB10:AB24) -> 20.01936 | AD25: =SUM(AD10:AD24) -> 20.01936 | AF25: =SUM(AF10:AF24) -> 12.155374 | AH25: =SUM(AH10:AH24) -> 32.174734 | AJ25: =SUM(AJ10:AJ24) -> 32.174734 | AL25: =SUM(AL10:AL24) -> 17.127037 | AN25: =SUM(AN10:AN24) -> 49.301771 | AP25: =SUM(AP10:AP24) -> 49.301771 | AR25: =SUM(AR10:AR24) -> -49.301771 | AT25: =SUM(AT10:AT24) -> 0 | AV25: =SUM(AV10:AV24) -> 0 | AX25: =SUM(AX10:AX24) -> 0 | AZ25: =SUM(AZ10:AZ24) -> 0 | BB25: =SUM(BB10:BB24) -> 0 | BD25: =SUM(BD10:BD24) -> 0 | BF25: =SUM(BF10:BF24) -> 0
C27: Rencana Minggu ini | D27: = | E27: ='T_Scedule Rkp'!E29 -> 0.31565657 | K27: ='T_Scedule Rkp'!F29 -> 3.4405388 | Q27: ='T_Scedule Rkp'!G29 -> 5.4508753 | W27: ='T_Scedule Rkp'!H29 -> 4.9888451 | AC27: ='T_Scedule Rkp'!I29 -> 5.1915539 | AI27: ='T_Scedule Rkp'!J29 -> 11.398858 | AO27: ='T_Scedule Rkp'!K29 -> 21.393093 | AU27: ='T_Scedule Rkp'!L29 -> 35.401067 | BA27: ='T_Scedule Rkp'!M29 -> 12.419512
C28: Rencana Kumulatif | D28: = | E28: ='T_Scedule Rkp'!E30 -> 0.31565657 | K28: ='T_Scedule Rkp'!F30 -> 3.7561954 | Q28: ='T_Scedule Rkp'!G30 -> 9.2070707 | W28: ='T_Scedule Rkp'!H30 -> 14.195916 | AC28: ='T_Scedule Rkp'!I30 -> 19.38747 | AI28: ='T_Scedule Rkp'!J30 -> 30.786328 | AO28: ='T_Scedule Rkp'!K30 -> 52.179421 | AU28: ='T_Scedule Rkp'!L30 -> 87.580488 | BA28: ='T_Scedule Rkp'!M30 -> 100
C29: Realisasi Minggu ini | D29: = | E29: =H25 -> 0 | K29: =N25 -> 0 | Q29: =T25 -> 4.0551347 | W29: =Z25 -> 15.964226 | AC29: =AF25 -> 12.155374 | AI29: =AL25 -> 17.127037 | AO29: =AR25 -> -49.301771 | AU29: =AX25 -> 0 | BA29: =BD25 -> 0
C30: Realisasi Kumulatif | D30: = | E30: =J25 -> 0 | K30: =P25 -> 0 | Q30: =V25 -> 4.0551347 | W30: =AB25 -> 20.01936 | AC30: =AH25 -> 32.174734 | AI30: =AN25 -> 49.301771 | AO30: =AT25 -> 0 | AU30: =AZ25 -> 0 | BA30: =BF25 -> 0
C31: Deviasi | D31: = | E31: =E30-E28 -> -0.31565657 | K31: =K30-K28 -> -3.7561954 | Q31: =Q30-Q28 -> -5.151936 | W31: =W30-W28 -> 5.8234444 | AC31: =AC30-AC28 -> 12.787264 | AI31: =AI30-AI28 -> 18.515444 | AO31: =AO30-AO28 -> -52.179421 | AU31: =AU30-AU28 -> -87.580488 | BA31: =BA30-BA28 -> -100

Sheet Rincian_Prog
B1: PROGRES PEKERJAAN
B2: =Cover!C7 -> PEMBUATAN INTERIOR KANTOR REGIONAL III PT ASDP INDONESIA FERRY
B3: Pakuwon Tower Lantai 22, Jl. Embong Malang No. 32-36, Kedungdoro, Kec. Tegalsari | N3: Week : | O3: 1 | T3: Week : | U3: =O3+1 -> 2 | Z3: Week : | AA3: =U3+1 -> 3 | AF3: Week : | AG3: =AA3+1 -> 4 | AL3: Week : | AM3: =AG3+1 -> 5 | AR3: Week : | AS3: =AM3+1 -> 6 | AX3: Week : | AY3: =AS3+1 -> 7 | BD3: Week : | BE3: =AY3+1 -> 8 | BJ3: Week : | BK3: =BE3+1 -> 9
B4: Surabaya | N4: Mulai : | O4: =VLOOKUP(O3,mingguanptasdp,2) -> 46226 | T4: Mulai : | U4: =VLOOKUP(U3,mingguanptasdp,2) -> 46230 | Z4: Mulai : | AA4: =VLOOKUP(AA3,mingguanptasdp,2) -> 46237 | AF4: Mulai : | AG4: =VLOOKUP(AG3,mingguanptasdp,2) -> 46244 | AL4: Mulai : | AM4: =VLOOKUP(AM3,mingguanptasdp,2) -> 46251 | AR4: Mulai : | AS4: =VLOOKUP(AS3,mingguanptasdp,2) -> 46258 | AX4: Mulai : | AY4: =VLOOKUP(AY3,mingguanptasdp,2) -> 46265 | BD4: Mulai : | BE4: =VLOOKUP(BE3,mingguanptasdp,2) -> 46272 | BJ4: Mulai : | BK4: =VLOOKUP(BK3,mingguanptasdp,2) -> 46279
N5: Hingga : | O5: =VLOOKUP(O3,mingguanptasdp,3) -> 46229 | T5: Hingga : | U5: =VLOOKUP(U3,mingguanptasdp,3) -> 46236 | Z5: Hingga : | AA5: =VLOOKUP(AA3,mingguanptasdp,3) -> 46243 | AF5: Hingga : | AG5: =VLOOKUP(AG3,mingguanptasdp,3) -> 46250 | AL5: Hingga : | AM5: =VLOOKUP(AM3,mingguanptasdp,3) -> 46257 | AR5: Hingga : | AS5: =VLOOKUP(AS3,mingguanptasdp,3) -> 46264 | AX5: Hingga : | AY5: =VLOOKUP(AY3,mingguanptasdp,3) -> 46271 | BD5: Hingga : | BE5: =VLOOKUP(BE3,mingguanptasdp,3) -> 46278 | BJ5: Hingga : | BK5: =VLOOKUP(BK3,mingguanptasdp,3) -> 46285
B6: NO | C6: ITEM PEKERJAAN | D6: KODE GBR | E6: VOLUME | F6: SATUAN | G6: HARGA SATUAN | H6: TOTAL HARGA | I6: BOBOT | J6: KEMAJUAN PEKERJAAN MINGGUAN | P6: KEMAJUAN PEKERJAAN MINGGUAN | V6: KEMAJUAN PEKERJAAN MINGGUAN | AB6: KEMAJUAN PEKERJAAN MINGGUAN | AH6: KEMAJUAN PEKERJAAN MINGGUAN | AN6: KEMAJUAN PEKERJAAN MINGGUAN | AT6: KEMAJUAN PEKERJAAN MINGGUAN | AZ6: KEMAJUAN PEKERJAAN MINGGUAN | BF6: KEMAJUAN PEKERJAAN MINGGUAN
J7: MINGGU LALU | L7: MINGGU INI | N7: S/D MINGGU INI | P7: MINGGU LALU | R7: MINGGU INI | T7: S/D MINGGU INI | V7: MINGGU LALU | X7: MINGGU INI | Z7: S/D MINGGU INI | AB7: MINGGU LALU | AD7: MINGGU INI | AF7: S/D MINGGU INI | AH7: MINGGU LALU | AJ7: MINGGU INI | AL7: S/D MINGGU INI | AN7: MINGGU LALU | AP7: MINGGU INI | AR7: S/D MINGGU INI | AT7: MINGGU LALU | AV7: MINGGU INI | AX7: S/D MINGGU INI | AZ7: MINGGU LALU | BB7: MINGGU INI | BD7: S/D MINGGU INI | BF7: MINGGU LALU | BH7: MINGGU INI | BJ7: S/D MINGGU INI
J8: PRESTASI % | K8: BOBOT % | L8: PRESTASI % | M8: BOBOT % | N8: PRESTASI % | O8: BOBOT % | P8: PRESTASI % | Q8: BOBOT % | R8: PRESTASI % | S8: BOBOT % | T8: PRESTASI % | U8: BOBOT % | V8: PRESTASI % | W8: BOBOT % | X8: PRESTASI % | Y8: BOBOT % | Z8: PRESTASI % | AA8: BOBOT % | AB8: PRESTASI % | AC8: BOBOT % | AD8: PRESTASI % | AE8: BOBOT % | AF8: PRESTASI % | AG8: BOBOT % | AH8: PRESTASI % | AI8: BOBOT % | AJ8: PRESTASI % | AK8: BOBOT % | AL8: PRESTASI % | AM8: BOBOT % | AN8: PRESTASI % | AO8: BOBOT % | AP8: PRESTASI % | AQ8: BOBOT % | AR8: PRESTASI % | AS8: BOBOT % | AT8: PRESTASI % | AU8: BOBOT % | AV8: PRESTASI % | AW8: BOBOT % | AX8: PRESTASI % | AY8: BOBOT % | AZ8: PRESTASI % | BA8: BOBOT % | BB8: PRESTASI % | BC8: BOBOT % | BD8: PRESTASI % | BE8: BOBOT % | BF8: PRESTASI % | BG8: BOBOT % | BH8: PRESTASI % | BI8: BOBOT % | BJ8: PRESTASI % | BK8: BOBOT %
B9: 1 | C9: =B9+1 -> 2 | I9: =C9+1 -> 3 | J9: 4 | K9: =J9+1 -> 5 | L9: =K9+1 -> 6 | M9: =L9+1 -> 7 | N9: =M9+1 -> 8 | O9: =N9+1 -> 9 | P9: 4 | Q9: =P9+1 -> 5 | R9: =Q9+1 -> 6 | S9: =R9+1 -> 7 | T9: =S9+1 -> 8 | U9: =T9+1 -> 9 | V9: 4 | W9: =V9+1 -> 5 | X9: =W9+1 -> 6 | Y9: =X9+1 -> 7 | Z9: =Y9+1 -> 8 | AA9: =Z9+1 -> 9 | AB9: 4 | AC9: =AB9+1 -> 5 | AD9: =AC9+1 -> 6 | AE9: =AD9+1 -> 7 | AF9: =AE9+1 -> 8 | AG9: =AF9+1 -> 9 | AH9: 4 | AI9: =AH9+1 -> 5 | AJ9: =AI9+1 -> 6 | AK9: =AJ9+1 -> 7 | AL9: =AK9+1 -> 8 | AM9: =AL9+1 -> 9 | AN9: 4 | AO9: =AN9+1 -> 5 | AP9: =AO9+1 -> 6 | AQ9: =AP9+1 -> 7 | AR9: =AQ9+1 -> 8 | AS9: =AR9+1 -> 9 | AT9: 4 | AU9: =AT9+1 -> 5 | AV9: =AU9+1 -> 6 | AW9: =AV9+1 -> 7 | AX9: =AW9+1 -> 8 | AY9: =AX9+1 -> 9 | AZ9: 4 | BA9: =AZ9+1 -> 5 | BB9: =BA9+1 -> 6 | BC9: =BB9+1 -> 7 | BD9: =BC9+1 -> 8 | BE9: =BD9+1 -> 9 | BF9: 4 | BG9: =BF9+1 -> 5 | BH9: =BG9+1 -> 6 | BI9: =BH9+1 -> 7 | BJ9: =BI9+1 -> 8 | BK9: =BJ9+1 -> 9
B11: I | C11: PEKERJAAN PERSIAPAN
B12: 1 | C12: Marking dan pengukuran ulang | E12: 250 | F12: m2 | G12: 12500 | H12: =G12*E12 -> 3125000 | I12: =(H12/$H$197)*100 -> 0.52609428 | J12: 0 | K12: =J12*$I12 -> 0 | L12: =N12-J12 -> 0 | M12: =L12*$I12 -> 0 | N12: 0 | O12: =N12*$I12 -> 0 | P12: =N12 -> 0 | Q12: =P12*$I12 -> 0 | R12: =T12-P12 -> 0 | S12: =R12*$I12 -> 0 | T12: 0 | U12: =T12*$I12 -> 0 | V12: =T12 -> 0 | W12: =V12*$I12 -> 0 | X12: =Z12-V12 -> 0.5 | Y12: =X12*$I12 -> 0.26304714 | Z12: 0.5 | AA12: =Z12*$I12 -> 0.26304714 | AB12: =Z12 -> 0.5 | AC12: =AB12*$I12 -> 0.26304714 | AD12: =AF12-AB12 -> 0.5 | AE12: =AD12*$I12 -> 0.26304714 | AF12: 1 | AG12: =AF12*$I12 -> 0.52609428 | AH12: =AF12 -> 1 | AI12: =AH12*$I12 -> 0.52609428 | AJ12: =AL12-AH12 -> 0 | AK12: =AJ12*$I12 -> 0 | AL12: 1 | AM12: =AL12*$I12 -> 0.52609428 | AN12: =AL12 -> 1 | AO12: =AN12*$I12 -> 0.52609428 | AP12: =AR12-AN12 -> 0 | AQ12: =AP12*$I12 -> 0 | AR12: 1 | AS12: =AR12*$I12 -> 0.52609428 | AT12: =AR12 -> 1 | AU12: =AT12*$I12 -> 0.52609428 | AV12: =AX12-AT12 -> -1 | AW12: =AV12*$I12 -> -0.52609428 | AX12: 0 | AY12: =AX12*$I12 -> 0 | AZ12: =AX12 -> 0 | BA12: =AZ12*$I12 -> 0 | BB12: =BD12-AZ12 -> 0 | BC12: =BB12*$I12 -> 0 | BD12: 0 | BE12: =BD12*$I12 -> 0 | BF12: =BD12 -> 0 | BG12: =BF12*$I12 -> 0 | BH12: =BJ12-BF12 -> 0 | BI12: =BH12*$I12 -> 0 | BJ12: 0 | BK12: =BJ12*$I12 -> 0
B13: 2 | C13: Mobilisasi dan demobilisasi (meliputi material & tenaga kerja) | E13: 1 | F13: ls | G13: 5000000 | H13: =G13*E13 -> 5000000 | I13: =(H13/$H$197)*100 -> 0.84175084 | J13: 0 | K13: =J13*$I13 -> 0 | L13: =N13-J13 -> 0 | M13: =L13*$I13 -> 0 | N13: 0 | O13: =N13*$I13 -> 0 | P13: =N13 -> 0 | Q13: =P13*$I13 -> 0 | R13: =T13-P13 -> 0 | S13: =R13*$I13 -> 0 | T13: 0 | U13: =T13*$I13 -> 0 | V13: =T13 -> 0 | W13: =V13*$I13 -> 0 | X13: =Z13-V13 -> 0 | Y13: =X13*$I13 -> 0 | Z13: 0 | AA13: =Z13*$I13 -> 0 | AB13: =Z13 -> 0 | AC13: =AB13*$I13 -> 0 | AD13: =AF13-AB13 -> 1 | AE13: =AD13*$I13 -> 0.84175084 | AF13: 1 | AG13: =AF13*$I13 -> 0.84175084 | AH13: =AF13 -> 1 | AI13: =AH13*$I13 -> 0.84175084 | AJ13: =AL13-AH13 -> 0 | AK13: =AJ13*$I13 -> 0 | AL13: 1 | AM13: =AL13*$I13 -> 0.84175084 | AN13: =AL13 -> 1 | AO13: =AN13*$I13 -> 0.84175084 | AP13: =AR13-AN13 -> 0 | AQ13: =AP13*$I13 -> 0 | AR13: 1 | AS13: =AR13*$I13 -> 0.84175084 | AT13: =AR13 -> 1 | AU13: =AT13*$I13 -> 0.84175084 | AV13: =AX13-AT13 -> -1 | AW13: =AV13*$I13 -> -0.84175084 | AX13: 0 | AY13: =AX13*$I13 -> 0 | AZ13: =AX13 -> 0 | BA13: =AZ13*$I13 -> 0 | BB13: =BD13-AZ13 -> 0 | BC13: =BB13*$I13 -> 0 | BD13: 0 | BE13: =BD13*$I13 -> 0 | BF13: =BD13 -> 0 | BG13: =BF13*$I13 -> 0 | BH13: =BJ13-BF13 -> 0 | BI13: =BH13*$I13 -> 0 | BJ13: 0 | BK13: =BJ13*$I13 -> 0
B14: 3 | C14: Biaya Air dan Listrik selama pekerjaan | E14: 2 | F14: bulan | G14: 4000000 | H14: =G14*E14 -> 8000000 | I14: =(H14/$H$197)*100 -> 1.3468013 | J14: 0 | K14: =J14*$I14 -> 0 | L14: =N14-J14 -> 0 | M14: =L14*$I14 -> 0 | N14: 0 | O14: =N14*$I14 -> 0 | P14: =N14 -> 0 | Q14: =P14*$I14 -> 0 | R14: =T14-P14 -> 0 | S14: =R14*$I14 -> 0 | T14: 0 | U14: =T14*$I14 -> 0 | V14: =T14 -> 0 | W14: =V14*$I14 -> 0 | X14: =Z14-V14 -> 0 | Y14: =X14*$I14 -> 0 | Z14: 0 | AA14: =Z14*$I14 -> 0 | AB14: =Z14 -> 0 | AC14: =AB14*$I14 -> 0 | AD14: =AF14-AB14 -> 1 | AE14: =AD14*$I14 -> 1.3468013 | AF14: 1 | AG14: =AF14*$I14 -> 1.3468013 | AH14: =AF14 -> 1 | AI14: =AH14*$I14 -> 1.3468013 | AJ14: =AL14-AH14 -> 0 | AK14: =AJ14*$I14 -> 0 | AL14: 1 | AM14: =AL14*$I14 -> 1.3468013 | AN14: =AL14 -> 1 | AO14: =AN14*$I14 -> 1.3468013 | AP14: =AR14-AN14 -> 0 | AQ14: =AP14*$I14 -> 0 | AR14: 1 | AS14: =AR14*$I14 -> 1.3468013 | AT14: =AR14 -> 1 | AU14: =AT14*$I14 -> 1.3468013 | AV14: =AX14-AT14 -> -1 | AW14: =AV14*$I14 -> -1.3468013 | AX14: 0 | AY14: =AX14*$I14 -> 0 | AZ14: =AX14 -> 0 | BA14: =AZ14*$I14 -> 0 | BB14: =BD14-AZ14 -> 0 | BC14: =BB14*$I14 -> 0 | BD14: 0 | BE14: =BD14*$I14 -> 0 | BF14: =BD14 -> 0 | BG14: =BF14*$I14 -> 0 | BH14: =BJ14-BF14 -> 0 | BI14: =BH14*$I14 -> 0 | BJ14: 0 | BK14: =BJ14*$I14 -> 0
B15: 4 | C15: Biaya pengamanan barang di lokasi | E15: 2 | F15: bulan | G15: 3450000 | H15: =G15*E15 -> 6900000 | I15: =(H15/$H$197)*100 -> 1.1616162 | J15: 0 | K15: =J15*$I15 -> 0 | L15: =N15-J15 -> 0 | M15: =L15*$I15 -> 0 | N15: 0 | O15: =N15*$I15 -> 0 | P15: =N15 -> 0 | Q15: =P15*$I15 -> 0 | R15: =T15-P15 -> 0 | S15: =R15*$I15 -> 0 | T15: 0 | U15: =T15*$I15 -> 0 | V15: =T15 -> 0 | W15: =V15*$I15 -> 0 | X15: =Z15-V15 -> 0 | Y15: =X15*$I15 -> 0 | Z15: 0 | AA15: =Z15*$I15 -> 0 | AB15: =Z15 -> 0 | AC15: =AB15*$I15 -> 0 | AD15: =AF15-AB15 -> 1 | AE15: =AD15*$I15 -> 1.1616162 | AF15: 1 | AG15: =AF15*$I15 -> 1.1616162 | AH15: =AF15 -> 1 | AI15: =AH15*$I15 -> 1.1616162 | AJ15: =AL15-AH15 -> 0 | AK15: =AJ15*$I15 -> 0 | AL15: 1 | AM15: =AL15*$I15 -> 1.1616162 | AN15: =AL15 -> 1 | AO15: =AN15*$I15 -> 1.1616162 | AP15: =AR15-AN15 -> 0 | AQ15: =AP15*$I15 -> 0 | AR15: 1 | AS15: =AR15*$I15 -> 1.1616162 | AT15: =AR15 -> 1 | AU15: =AT15*$I15 -> 1.1616162 | AV15: =AX15-AT15 -> -1 | AW15: =AV15*$I15 -> -1.1616162 | AX15: 0 | AY15: =AX15*$I15 -> 0 | AZ15: =AX15 -> 0 | BA15: =AZ15*$I15 -> 0 | BB15: =BD15-AZ15 -> 0 | BC15: =BB15*$I15 -> 0 | BD15: 0 | BE15: =BD15*$I15 -> 0 | BF15: =BD15 -> 0 | BG15: =BF15*$I15 -> 0 | BH15: =BJ15-BF15 -> 0 | BI15: =BH15*$I15 -> 0 | BJ15: 0 | BK15: =BJ15*$I15 -> 0
B16: 5 | C16: Biaya Kebersihan proyek | E16: 2 | F16: bulan | G16: 3300000 | H16: =G16*E16 -> 6600000 | I16: =(H16/$H$197)*100 -> 1.1111111 | J16: 0 | K16: =J16*$I16 -> 0 | L16: =N16-J16 -> 0 | M16: =L16*$I16 -> 0 | N16: 0 | O16: =N16*$I16 -> 0 | P16: =N16 -> 0 | Q16: =P16*$I16 -> 0 | R16: =T16-P16 -> 0 | S16: =R16*$I16 -> 0 | T16: 0 | U16: =T16*$I16 -> 0 | V16: =T16 -> 0 | W16: =V16*$I16 -> 0 | X16: =Z16-V16 -> 0 | Y16: =X16*$I16 -> 0 | Z16: 0 | AA16: =Z16*$I16 -> 0 | AB16: =Z16 -> 0 | AC16: =AB16*$I16 -> 0 | AD16: =AF16-AB16 -> 1 | AE16: =AD16*$I16 -> 1.1111111 | AF16: 1 | AG16: =AF16*$I16 -> 1.1111111 | AH16: =AF16 -> 1 | AI16: =AH16*$I16 -> 1.1111111 | AJ16: =AL16-AH16 -> 0 | AK16: =AJ16*$I16 -> 0 | AL16: 1 | AM16: =AL16*$I16 -> 1.1111111 | AN16: =AL16 -> 1 | AO16: =AN16*$I16 -> 1.1111111 | AP16: =AR16-AN16 -> 0 | AQ16: =AP16*$I16 -> 0 | AR16: 1 | AS16: =AR16*$I16 -> 1.1111111 | AT16: =AR16 -> 1 | AU16: =AT16*$I16 -> 1.1111111 | AV16: =AX16-AT16 -> -1 | AW16: =AV16*$I16 -> -1.1111111 | AX16: 0 | AY16: =AX16*$I16 -> 0 | AZ16: =AX16 -> 0 | BA16: =AZ16*$I16 -> 0 | BB16: =BD16-AZ16 -> 0 | BC16: =BB16*$I16 -> 0 | BD16: 0 | BE16: =BD16*$I16 -> 0 | BF16: =BD16 -> 0 | BG16: =BF16*$I16 -> 0 | BH16: =BJ16-BF16 -> 0 | BI16: =BH16*$I16 -> 0 | BJ16: 0 | BK16: =BJ16*$I16 -> 0
B17: 6 | C17: Pengangkutan/Pembuangan puing bekas bongkaran ; satuan mobil truck engkel | E17: 5 | F17: rit | G17: 1350000 | H17: =G17*E17 -> 6750000 | I17: =(H17/$H$197)*100 -> 1.1363636 | J17: 0 | K17: =J17*$I17 -> 0 | L17: =N17-J17 -> 0 | M17: =L17*$I17 -> 0 | N17: 0 | O17: =N17*$I17 -> 0 | P17: =N17 -> 0 | Q17: =P17*$I17 -> 0 | R17: =T17-P17 -> 0 | S17: =R17*$I17 -> 0 | T17: 0 | U17: =T17*$I17 -> 0 | V17: =T17 -> 0 | W17: =V17*$I17 -> 0 | X17: =Z17-V17 -> 0 | Y17: =X17*$I17 -> 0 | Z17: 0 | AA17: =Z17*$I17 -> 0 | AB17: =Z17 -> 0 | AC17: =AB17*$I17 -> 0 | AD17: =AF17-AB17 -> 0.4 | AE17: =AD17*$I17 -> 0.45454545 | AF17: 0.4 | AG17: =AF17*$I17 -> 0.45454545 | AH17: =AF17 -> 0.4 | AI17: =AH17*$I17 -> 0.45454545 | AJ17: =AL17-AH17 -> 0.2 | AK17: =AJ17*$I17 -> 0.22727273 | AL17: 0.6 | AM17: =AL17*$I17 -> 0.68181818 | AN17: =AL17 -> 0.6 | AO17: =AN17*$I17 -> 0.68181818 | AP17: =AR17-AN17 -> 0.1 | AQ17: =AP17*$I17 -> 0.11363636 | AR17: 0.7 | AS17: =AR17*$I17 -> 0.79545455 | AT17: =AR17 -> 0.7 | AU17: =AT17*$I17 -> 0.79545455 | AV17: =AX17-AT17 -> -0.7 | AW17: =AV17*$I17 -> -0.79545455 | AX17: 0 | AY17: =AX17*$I17 -> 0 | AZ17: =AX17 -> 0 | BA17: =AZ17*$I17 -> 0 | BB17: =BD17-AZ17 -> 0 | BC17: =BB17*$I17 -> 0 | BD17: 0 | BE17: =BD17*$I17 -> 0 | BF17: =BD17 -> 0 | BG17: =BF17*$I17 -> 0 | BH17: =BJ17-BF17 -> 0 | BI17: =BH17*$I17 -> 0 | BJ17: 0 | BK17: =BJ17*$I17 -> 0
B18: 7 | C18: Peralatan dan Material Bantu (Scafolding, terpal Plastik, exhaust/blower dll ) | E18: 1 | F18: ls | G18: 3540000 | H18: =G18*E18 -> 3540000 | I18: =(H18/$H$197)*100 -> 0.5959596 | J18: 0 | K18: =J18*$I18 -> 0 | L18: =N18-J18 -> 0 | M18: =L18*$I18 -> 0 | N18: 0 | O18: =N18*$I18 -> 0 | P18: =N18 -> 0 | Q18: =P18*$I18 -> 0 | R18: =T18-P18 -> 0 | S18: =R18*$I18 -> 0 | T18: 0 | U18: =T18*$I18 -> 0 | V18: =T18 -> 0 | W18: =V18*$I18 -> 0 | X18: =Z18-V18 -> 0 | Y18: =X18*$I18 -> 0 | Z18: 0 | AA18: =Z18*$I18 -> 0 | AB18: =Z18 -> 0 | AC18: =AB18*$I18 -> 0 | AD18: =AF18-AB18 -> 1 | AE18: =AD18*$I18 -> 0.5959596 | AF18: 1 | AG18: =AF18*$I18 -> 0.5959596 | AH18: =AF18 -> 1 | AI18: =AH18*$I18 -> 0.5959596 | AJ18: =AL18-AH18 -> 0 | AK18: =AJ18*$I18 -> 0 | AL18: 1 | AM18: =AL18*$I18 -> 0.5959596 | AN18: =AL18 -> 1 | AO18: =AN18*$I18 -> 0.5959596 | AP18: =AR18-AN18 -> 0 | AQ18: =AP18*$I18 -> 0 | AR18: 1 | AS18: =AR18*$I18 -> 0.5959596 | AT18: =AR18 -> 1 | AU18: =AT18*$I18 -> 0.5959596 | AV18: =AX18-AT18 -> -1 | AW18: =AV18*$I18 -> -0.5959596 | AX18: 0 | AY18: =AX18*$I18 -> 0 | AZ18: =AX18 -> 0 | BA18: =AZ18*$I18 -> 0 | BB18: =BD18-AZ18 -> 0 | BC18: =BB18*$I18 -> 0 | BD18: 0 | BE18: =BD18*$I18 -> 0 | BF18: =BD18 -> 0 | BG18: =BF18*$I18 -> 0 | BH18: =BJ18-BF18 -> 0 | BI18: =BH18*$I18 -> 0 | BJ18: 0 | BK18: =BJ18*$I18 -> 0
B19: 8 | C19: Hard copy As Built drawing dan approval material | E19: 1 | F19: Ls | G19: 8000000 | H19: =G19*E19 -> 8000000 | I19: =(H19/$H$197)*100 -> 1.3468013 | J19: 0 | K19: =J19*$I19 -> 0 | L19: =N19-J19 -> 0 | M19: =L19*$I19 -> 0 | N19: 0 | O19: =N19*$I19 -> 0 | P19: =N19 -> 0 | Q19: =P19*$I19 -> 0 | R19: =T19-P19 -> 0 | S19: =R19*$I19 -> 0 | T19: 0 | U19: =T19*$I19 -> 0 | V19: =T19 -> 0 | W19: =V19*$I19 -> 0 | X19: =Z19-V19 -> 0.8 | Y19: =X19*$I19 -> 1.0774411 | Z19: 0.8 | AA19: =Z19*$I19 -> 1.0774411 | AB19: =Z19 -> 0.8 | AC19: =AB19*$I19 -> 1.0774411 | AD19: =AF19-AB19 -> 0.2 | AE19: =AD19*$I19 -> 0.26936027 | AF19: 1 | AG19: =AF19*$I19 -> 1.3468013 | AH19: =AF19 -> 1 | AI19: =AH19*$I19 -> 1.3468013 | AJ19: =AL19-AH19 -> 0 | AK19: =AJ19*$I19 -> 0 | AL19: 1 | AM19: =AL19*$I19 -> 1.3468013 | AN19: =AL19 -> 1 | AO19: =AN19*$I19 -> 1.3468013 | AP19: =AR19-AN19 -> 0 | AQ19: =AP19*$I19 -> 0 | AR19: 1 | AS19: =AR19*$I19 -> 1.3468013 | AT19: =AR19 -> 1 | AU19: =AT19*$I19 -> 1.3468013 | AV19: =AX19-AT19 -> -1 | AW19: =AV19*$I19 -> -1.3468013 | AX19: 0 | AY19: =AX19*$I19 -> 0 | AZ19: =AX19 -> 0 | BA19: =AZ19*$I19 -> 0 | BB19: =BD19-AZ19 -> 0 | BC19: =BB19*$I19 -> 0 | BD19: 0 | BE19: =BD19*$I19 -> 0 | BF19: =BD19 -> 0 | BG19: =BF19*$I19 -> 0 | BH19: =BJ19-BF19 -> 0 | BI19: =BH19*$I19 -> 0 | BJ19: 0 | BK19: =BJ19*$I19 -> 0
B20: 9 | C20: Deposit Gedung | E20: 1 | F20: Ls | G20: 7500000 | H20: =G20*E20 -> 7500000 | I20: =(H20/$H$197)*100 -> 1.2626263 | J20: 0 | K20: =J20*$I20 -> 0 | L20: =N20-J20 -> 0 | M20: =L20*$I20 -> 0 | N20: 0 | O20: =N20*$I20 -> 0 | P20: =N20 -> 0 | Q20: =P20*$I20 -> 0 | R20: =T20-P20 -> 0 | S20: =R20*$I20 -> 0 | T20: 0 | U20: =T20*$I20 -> 0 | V20: =T20 -> 0 | W20: =V20*$I20 -> 0 | X20: =Z20-V20 -> 0 | Y20: =X20*$I20 -> 0 | Z20: 0 | AA20: =Z20*$I20 -> 0 | AB20: =Z20 -> 0 | AC20: =AB20*$I20 -> 0 | AD20: =AF20-AB20 -> 1 | AE20: =AD20*$I20 -> 1.2626263 | AF20: 1 | AG20: =AF20*$I20 -> 1.2626263 | AH20: =AF20 -> 1 | AI20: =AH20*$I20 -> 1.2626263 | AJ20: =AL20-AH20 -> 0 | AK20: =AJ20*$I20 -> 0 | AL20: 1 | AM20: =AL20*$I20 -> 1.2626263 | AN20: =AL20 -> 1 | AO20: =AN20*$I20 -> 1.2626263 | AP20: =AR20-AN20 -> 0 | AQ20: =AP20*$I20 -> 0 | AR20: 1 | AS20: =AR20*$I20 -> 1.2626263 | AT20: =AR20 -> 1 | AU20: =AT20*$I20 -> 1.2626263 | AV20: =AX20-AT20 -> -1 | AW20: =AV20*$I20 -> -1.2626263 | AX20: 0 | AY20: =AX20*$I20 -> 0 | AZ20: =AX20 -> 0 | BA20: =AZ20*$I20 -> 0 | BB20: =BD20-AZ20 -> 0 | BC20: =BB20*$I20 -> 0 | BD20: 0 | BE20: =BD20*$I20 -> 0 | BF20: =BD20 -> 0 | BG20: =BF20*$I20 -> 0 | BH20: =BJ20-BF20 -> 0 | BI20: =BH20*$I20 -> 0 | BJ20: 0 | BK20: =BJ20*$I20 -> 0
G22: Sub Total Persiapan | H22: =SUM(H12:H21) -> 55415000
B24: II | C24: PEKERJAAN FIT OUT INTERIOR DAN ARSITEKTUR
B25: II.A | C25: Pekerjaan Ruang Staff & Resepsionis
B27: 1 | C27: Screeding & levelling lantai | D27: CP1 | E27: 186.407 | F27: m2 | G27: 129000 | H27: =G27*E27 -> 24046503 | I27: =(H27/$H$197)*100 -> 4.0482328 | J27: 0 | K27: =J27*$I27 -> 0 | L27: =N27-J27 -> 0 | M27: =L27*$I27 -> 0 | N27: 0 | O27: =N27*$I27 -> 0 | P27: =N27 -> 0 | Q27: =P27*$I27 -> 0 | R27: =T27-P27 -> 0 | S27: =R27*$I27 -> 0 | T27: 0 | U27: =T27*$I27 -> 0 | V27: =T27 -> 0 | W27: =V27*$I27 -> 0 | X27: =Z27-V27 -> 0.5 | Y27: =X27*$I27 -> 2.0241164 | Z27: 0.5 | AA27: =Z27*$I27 -> 2.0241164 | AB27: =Z27 -> 0.5 | AC27: =AB27*$I27 -> 2.0241164 | AD27: =AF27-AB27 -> 0.5 | AE27: =AD27*$I27 -> 2.0241164 | AF27: 1 | AG27: =AF27*$I27 -> 4.0482328 | AH27: =AF27 -> 1 | AI27: =AH27*$I27 -> 4.0482328 | AJ27: =AL27-AH27 -> 0 | AK27: =AJ27*$I27 -> 0 | AL27: 1 | AM27: =AL27*$I27 -> 4.0482328 | AN27: =AL27 -> 1 | AO27: =AN27*$I27 -> 4.0482328 | AP27: =AR27-AN27 -> 0 | AQ27: =AP27*$I27 -> 0 | AR27: 1 | AS27: =AR27*$I27 -> 4.0482328 | AT27: =AR27 -> 1 | AU27: =AT27*$I27 -> 4.0482328 | AV27: =AX27-AT27 -> -1 | AW27: =AV27*$I27 -> -4.0482328 | AX27: 0 | AY27: =AX27*$I27 -> 0 | AZ27: =AX27 -> 0 | BA27: =AZ27*$I27 -> 0 | BB27: =BD27-AZ27 -> 0 | BC27: =BB27*$I27 -> 0 | BD27: 0 | BE27: =BD27*$I27 -> 0 | BF27: =BD27 -> 0 | BG27: =BF27*$I27 -> 0 | BH27: =BJ27-BF27 -> 0 | BI27: =BH27*$I27 -> 0 | BJ27: 0 | BK27: =BJ27*$I27 -> 0
B29: 2 | C29: Pengadaan dan pasang penutup lantai Carpet Flowing Plank | D29: CP1 | E29: 186.407 | F29: m2 | G29: 706000 | H29: =G29*E29 -> 1.3160334e+08 | I29: =(H29/$H$197)*100 -> 22.155445 | J29: 0 | K29: =J29*$I29 -> 0 | L29: =N29-J29 -> 0 | M29: =L29*$I29 -> 0 | N29: 0 | O29: =N29*$I29 -> 0 | P29: =N29 -> 0 | Q29: =P29*$I29 -> 0 | R29: =T29-P29 -> 0 | S29: =R29*$I29 -> 0 | T29: 0 | U29: =T29*$I29 -> 0 | V29: =T29 -> 0 | W29: =V29*$I29 -> 0 | X29: =Z29-V29 -> 0 | Y29: =X29*$I29 -> 0 | Z29: 0 | AA29: =Z29*$I29 -> 0 | AB29: =Z29 -> 0 | AC29: =AB29*$I29 -> 0 | AD29: =AF29-AB29 -> 0.2 | AE29: =AD29*$I29 -> 4.431089 | AF29: 0.2 | AG29: =AF29*$I29 -> 4.431089 | AH29: =AF29 -> 0.2 | AI29: =AH29*$I29 -> 4.431089 | AJ29: =AL29-AH29 -> 0.15 | AK29: =AJ29*$I29 -> 3.3233167 | AL29: 0.35 | AM29: =AL29*$I29 -> 7.7544057 | AN29: =AL29 -> 0.35 | AO29: =AN29*$I29 -> 7.7544057 | AP29: =AR29-AN29 -> 0.15 | AQ29: =AP29*$I29 -> 3.3233167 | AR29: 0.5 | AS29: =AR29*$I29 -> 11.077722 | AT29: =AR29 -> 0.5 | AU29: =AT29*$I29 -> 11.077722 | AV29: =AX29-AT29 -> -0.5 | AW29: =AV29*$I29 -> -11.077722 | AX29: 0 | AY29: =AX29*$I29 -> 0 | AZ29: =AX29 -> 0 | BA29: =AZ29*$I29 -> 0 | BB29: =BD29-AZ29 -> 0 | BC29: =BB29*$I29 -> 0 | BD29: 0 | BE29: =BD29*$I29 -> 0 | BF29: =BD29 -> 0 | BG29: =BF29*$I29 -> 0 | BH29: =BJ29-BF29 -> 0 | BI29: =BH29*$I29 -> 0 | BJ29: 0 | BK29: =BJ29*$I29 -> 0
B32: =B29+1 -> 3 | C32: Pek Finishing Dinding dan Partisi | D32: PT1 | E32: 96.518 | F32: m2 | G32: 45000 | H32: =G32*E32 -> 4343310 | I32: =(H32/$H$197)*100 -> 0.73119697 | J32: 0 | K32: =J32*$I32 -> 0 | L32: =N32-J32 -> 0 | M32: =L32*$I32 -> 0 | N32: 0 | O32: =N32*$I32 -> 0 | P32: =N32 -> 0 | Q32: =P32*$I32 -> 0 | R32: =T32-P32 -> 0 | S32: =R32*$I32 -> 0 | T32: 0 | U32: =T32*$I32 -> 0 | V32: =T32 -> 0 | W32: =V32*$I32 -> 0 | X32: =Z32-V32 -> 0 | Y32: =X32*$I32 -> 0 | Z32: 0 | AA32: =Z32*$I32 -> 0 | AB32: =Z32 -> 0 | AC32: =AB32*$I32 -> 0 | AD32: =AF32-AB32 -> 0 | AE32: =AD32*$I32 -> 0 | AF32: 0 | AG32: =AF32*$I32 -> 0 | AH32: =AF32 -> 0 | AI32: =AH32*$I32 -> 0 | AJ32: =AL32-AH32 -> 0 | AK32: =AJ32*$I32 -> 0 | AL32: 0 | AM32: =AL32*$I32 -> 0 | AN32: =AL32 -> 0 | AO32: =AN32*$I32 -> 0 | AP32: =AR32-AN32 -> 0.1 | AQ32: =AP32*$I32 -> 0.073119697 | AR32: 0.1 | AS32: =AR32*$I32 -> 0.073119697 | AT32: =AR32 -> 0.1 | AU32: =AT32*$I32 -> 0.073119697 | AV32: =AX32-AT32 -> -0.1 | AW32: =AV32*$I32 -> -0.073119697 | AX32: 0 | AY32: =AX32*$I32 -> 0 | AZ32: =AX32 -> 0 | BA32: =AZ32*$I32 -> 0 | BB32: =BD32-AZ32 -> 0 | BC32: =BB32*$I32 -> 0 | BD32: 0 | BE32: =BD32*$I32 -> 0 | BF32: =BD32 -> 0 | BG32: =BF32*$I32 -> 0 | BH32: =BJ32-BF32 -> 0 | BI32: =BH32*$I32 -> 0 | BJ32: 0 | BK32: =BJ32*$I32 -> 0
C33: Material : Dulux
B35: =B32+1 -> 4 | C35: Pengadaan dan pasang plint lantai | D35: TB1 | E35: 34.547 | F35: m' | G35: 87000 | H35: =G35*E35 -> 3005589 | I35: =(H35/$H$197)*100 -> 0.50599141 | J35: 0 | K35: =J35*$I35 -> 0 | L35: =N35-J35 -> 0 | M35: =L35*$I35 -> 0 | N35: 0 | O35: =N35*$I35 -> 0 | P35: =N35 -> 0 | Q35: =P35*$I35 -> 0 | R35: =T35-P35 -> 0 | S35: =R35*$I35 -> 0 | T35: 0 | U35: =T35*$I35 -> 0 | V35: =T35 -> 0 | W35: =V35*$I35 -> 0 | X35: =Z35-V35 -> 0 | Y35: =X35*$I35 -> 0 | Z35: 0 | AA35: =Z35*$I35 -> 0 | AB35: =Z35 -> 0 | AC35: =AB35*$I35 -> 0 | AD35: =AF35-AB35 -> 0 | AE35: =AD35*$I35 -> 0 | AF35: 0 | AG35: =AF35*$I35 -> 0 | AH35: =AF35 -> 0 | AI35: =AH35*$I35 -> 0 | AJ35: =AL35-AH35 -> 0 | AK35: =AJ35*$I35 -> 0 | AL35: 0 | AM35: =AL35*$I35 -> 0 | AN35: =AL35 -> 0 | AO35: =AN35*$I35 -> 0 | AP35: =AR35-AN35 -> 0 | AQ35: =AP35*$I35 -> 0 | AR35: 0 | AS35: =AR35*$I35 -> 0 | AT35: =AR35 -> 0 | AU35: =AT35*$I35 -> 0 | AV35: =AX35-AT35 -> 0 | AW35: =AV35*$I35 -> 0 | AX35: 0 | AY35: =AX35*$I35 -> 0 | AZ35: =AX35 -> 0 | BA35: =AZ35*$I35 -> 0 | BB35: =BD35-AZ35 -> 0 | BC35: =BB35*$I35 -> 0 | BD35: 0 | BE35: =BD35*$I35 -> 0 | BF35: =BD35 -> 0 | BG35: =BF35*$I35 -> 0 | BH35: =BJ35-BF35 -> 0 | BI35: =BH35*$I35 -> 0 | BJ35: 0 | BK35: =BJ35*$I35 -> 0
C36: Material : HPL tinggi 10 cm x tebal 1 cm
B38: =B35+1 -> 5 | C38: Pek Signed ASDP Uk. 135 x 100 cm | E38: 1 | F38: unit | G38: 5207000 | H38: =G38*E38 -> 5207000 | I38: =(H38/$H$197)*100 -> 0.87659933 | J38: 0 | K38: =J38*$I38 -> 0 | L38: =N38-J38 -> 0 | M38: =L38*$I38 -> 0 | N38: 0 | O38: =N38*$I38 -> 0 | P38: =N38 -> 0 | Q38: =P38*$I38 -> 0 | R38: =T38-P38 -> 0 | S38: =R38*$I38 -> 0 | T38: 0 | U38: =T38*$I38 -> 0 | V38: =T38 -> 0 | W38: =V38*$I38 -> 0 | X38: =Z38-V38 -> 0 | Y38: =X38*$I38 -> 0 | Z38: 0 | AA38: =Z38*$I38 -> 0 | AB38: =Z38 -> 0 | AC38: =AB38*$I38 -> 0 | AD38: =AF38-AB38 -> 0 | AE38: =AD38*$I38 -> 0 | AF38: 0 | AG38: =AF38*$I38 -> 0 | AH38: =AF38 -> 0 | AI38: =AH38*$I38 -> 0 | AJ38: =AL38-AH38 -> 0 | AK38: =AJ38*$I38 -> 0 | AL38: 0 | AM38: =AL38*$I38 -> 0 | AN38: =AL38 -> 0 | AO38: =AN38*$I38 -> 0 | AP38: =AR38-AN38 -> 0 | AQ38: =AP38*$I38 -> 0 | AR38: 0 | AS38: =AR38*$I38 -> 0 | AT38: =AR38 -> 0 | AU38: =AT38*$I38 -> 0 | AV38: =AX38-AT38 -> 0 | AW38: =AV38*$I38 -> 0 | AX38: 0 | AY38: =AX38*$I38 -> 0 | AZ38: =AX38 -> 0 | BA38: =AZ38*$I38 -> 0 | BB38: =BD38-AZ38 -> 0 | BC38: =BB38*$I38 -> 0 | BD38: 0 | BE38: =BD38*$I38 -> 0 | BF38: =BD38 -> 0 | BG38: =BF38*$I38 -> 0 | BH38: =BJ38-BF38 -> 0 | BI38: =BH38*$I38 -> 0 | BJ38: 0 | BK38: =BJ38*$I38 -> 0
B40: =B38+1 -> 6 | C40: Backdrop Resepsionis | E40: 1 | F40: Ls | G40: 21856000 | H40: =G40*E40 -> 21856000 | I40: =(H40/$H$197)*100 -> 3.6794613 | J40: 0 | K40: =J40*$I40 -> 0 | L40: =N40-J40 -> 0 | M40: =L40*$I40 -> 0 | N40: 0 | O40: =N40*$I40 -> 0 | P40: =N40 -> 0 | Q40: =P40*$I40 -> 0 | R40: =T40-P40 -> 0 | S40: =R40*$I40 -> 0 | T40: 0 | U40: =T40*$I40 -> 0 | V40: =T40 -> 0 | W40: =V40*$I40 -> 0 | X40: =Z40-V40 -> 0 | Y40: =X40*$I40 -> 0 | Z40: 0 | AA40: =Z40*$I40 -> 0 | AB40: =Z40 -> 0 | AC40: =AB40*$I40 -> 0 | AD40: =AF40-AB40 -> 0 | AE40: =AD40*$I40 -> 0 | AF40: 0 | AG40: =AF40*$I40 -> 0 | AH40: =AF40 -> 0 | AI40: =AH40*$I40 -> 0 | AJ40: =AL40-AH40 -> 0 | AK40: =AJ40*$I40 -> 0 | AL40: 0 | AM40: =AL40*$I40 -> 0 | AN40: =AL40 -> 0 | AO40: =AN40*$I40 -> 0 | AP40: =AR40-AN40 -> 0.4 | AQ40: =AP40*$I40 -> 1.4717845 | AR40: 0.4 | AS40: =AR40*$I40 -> 1.4717845 | AT40: =AR40 -> 0.4 | AU40: =AT40*$I40 -> 1.4717845 | AV40: =AX40-AT40 -> -0.4 | AW40: =AV40*$I40 -> -1.4717845 | AX40: 0 | AY40: =AX40*$I40 -> 0 | AZ40: =AX40 -> 0 | BA40: =AZ40*$I40 -> 0 | BB40: =BD40-AZ40 -> 0 | BC40: =BB40*$I40 -> 0 | BD40: 0 | BE40: =BD40*$I40 -> 0 | BF40: =BD40 -> 0 | BG40: =BF40*$I40 -> 0 | BH40: =BJ40-BF40 -> 0 | BI40: =BH40*$I40 -> 0 | BJ40: 0 | BK40: =BJ40*$I40 -> 0
C41: 4680 X 2820 mm (COS)
B43: =B40+1 -> 7 | C43: Dry Pantry Workcafé | E43: 1 | F43: Ls | G43: 19145000 | H43: =G43*E43 -> 19145000 | I43: =(H43/$H$197)*100 -> 3.223064 | J43: 0 | K43: =J43*$I43 -> 0 | L43: =N43-J43 -> 0 | M43: =L43*$I43 -> 0 | N43: 0 | O43: =N43*$I43 -> 0 | P43: =N43 -> 0 | Q43: =P43*$I43 -> 0 | R43: =T43-P43 -> 0 | S43: =R43*$I43 -> 0 | T43: 0 | U43: =T43*$I43 -> 0 | V43: =T43 -> 0 | W43: =V43*$I43 -> 0 | X43: =Z43-V43 -> 0 | Y43: =X43*$I43 -> 0 | Z43: 0 | AA43: =Z43*$I43 -> 0 | AB43: =Z43 -> 0 | AC43: =AB43*$I43 -> 0 | AD43: =AF43-AB43 -> 0 | AE43: =AD43*$I43 -> 0 | AF43: 0 | AG43: =AF43*$I43 -> 0 | AH43: =AF43 -> 0 | AI43: =AH43*$I43 -> 0 | AJ43: =AL43-AH43 -> 0 | AK43: =AJ43*$I43 -> 0 | AL43: 0 | AM43: =AL43*$I43 -> 0 | AN43: =AL43 -> 0 | AO43: =AN43*$I43 -> 0 | AP43: =AR43-AN43 -> 0 | AQ43: =AP43*$I43 -> 0 | AR43: 0 | AS43: =AR43*$I43 -> 0 | AT43: =AR43 -> 0 | AU43: =AT43*$I43 -> 0 | AV43: =AX43-AT43 -> 0 | AW43: =AV43*$I43 -> 0 | AX43: 0 | AY43: =AX43*$I43 -> 0 | AZ43: =AX43 -> 0 | BA43: =AZ43*$I43 -> 0 | BB43: =BD43-AZ43 -> 0 | BC43: =BB43*$I43 -> 0 | BD43: 0 | BE43: =BD43*$I43 -> 0 | BF43: =BD43 -> 0 | BG43: =BF43*$I43 -> 0 | BH43: =BJ43-BF43 -> 0 | BI43: =BH43*$I43 -> 0 | BJ43: 0 | BK43: =BJ43*$I43 -> 0
C44: 2500 X 600 X 2820 mm (COS)
C45: - Top table + Backsplash solid surface (ST1)
C46: - Dinding lapis keramik (CRT1)
C47: - Adjuster plywood 9 mm fin. HPL (LM7)
C48: - Body cabinet plywood 20 mm fin. HPL (LM7) + PVC edging
C49: - Pintu cabinet plywood 20 mm fin. HPL (LM7) + PVC edging
C50: - Pintu cabinet + drawer bawah plywood 20 mm fin. HPL ex. Taco TH889FC French Tan Oak (LM4) + PVC edging
C51: - Skirting cabinet bawah plywood fin. HPL (LM4)
...

Sheet T_Scedule Rkp
B1: TIME SCHEDULE
B2: =Cover!C7 -> PEMBUATAN INTERIOR KANTOR REGIONAL III PT ASDP INDONESIA FERRY
B3: Pakuwon Tower Lantai 22, Jl. Embong Malang No. 32-36, Kedungdoro, Kec. Tegalsari
B4: Surabaya
B6: NO | C6: ITEM PEKERJAAN | D6: BOBOT | E6: 1 | F6: =E6+1 -> 2 | G6: =F6+1 -> 3 | H6: =G6+1 -> 4 | I6: =H6+1 -> 5 | J6: =I6+1 -> 6 | K6: =J6+1 -> 7 | L6: =K6+1 -> 8 | M6: =L6+1 -> 9
E7: =VLOOKUP(E6,mingguanptasdp,2) -> 46226 | F7: =VLOOKUP(F6,mingguanptasdp,2) -> 46230 | G7: =VLOOKUP(G6,mingguanptasdp,2) -> 46237 | H7: =VLOOKUP(H6,mingguanptasdp,2) -> 46244 | I7: =VLOOKUP(I6,mingguanptasdp,2) -> 46251 | J7: =VLOOKUP(J6,mingguanptasdp,2) -> 46258 | K7: =VLOOKUP(K6,mingguanptasdp,2) -> 46265 | L7: =VLOOKUP(L6,mingguanptasdp,2) -> 46272 | M7: =VLOOKUP(M6,mingguanptasdp,2) -> 46279
E8: =VLOOKUP(E6,mingguanptasdp,3) -> 46229 | F8: =VLOOKUP(F6,mingguanptasdp,3) -> 46236 | G8: =VLOOKUP(G6,mingguanptasdp,3) -> 46243 | H8: =VLOOKUP(H6,mingguanptasdp,3) -> 46250 | I8: =VLOOKUP(I6,mingguanptasdp,3) -> 46257 | J8: =VLOOKUP(J6,mingguanptasdp,3) -> 46264 | K8: =VLOOKUP(K6,mingguanptasdp,3) -> 46271 | L8: =VLOOKUP(L6,mingguanptasdp,3) -> 46278 | M8: =VLOOKUP(M6,mingguanptasdp,3) -> 46285
B9: 1 | C9: =B9+1 -> 2 | D9: =C9+1 -> 3 | E9: =D9+1 -> 4 | F9: =E9+1 -> 5 | G9: =F9+1 -> 6 | H9: =G9+1 -> 7 | I9: =H9+1 -> 8 | J9: =I9+1 -> 9 | ... M9: =L9+1 -> 12
A11: p | B11: =Rincian_Prog!B11 -> I | C11: =Rincian_Prog!C11 -> PEKERJAAN PERSIAPAN | D11: =SUM(Rincian_Prog!I12:I20) -> 9.3291246 | E11: =SUM('T_Scedule Rinc'!E11,'T_Scedule Rinc'!E13,'T_Scedule Rinc'!E15,'T_Scedule Rinc'!E17,'T_Scedule Rinc'!E19,'T_Scedule Rinc'!E21,'T_Scedule Rinc'!E23,'T_Scedule Rinc'!E25,'T_Scedule Rinc'!E27) -> 0.31565657 | F11: =SUM('T_Scedule Rinc'!F11,'T_Scedule Rinc'!F13,'T_Scedule Rinc'!F15,'T_Scedule Rinc'!F17,'T_Scedule Rinc'!F19,'T_Scedule Rinc'!F21,'T_Scedule Rinc'!F23,'T_Scedule Rinc'!F25,'T_Scedule Rinc'!F27) -> 2.6308923 | G11: =SUM('T_Scedule Rinc'!G11,'T_Scedule Rinc'!G13,'T_Scedule Rinc'!G15,'T_Scedule Rinc'!G17,'T_Scedule Rinc'!G19,'T_Scedule Rinc'!G21,'T_Scedule Rinc'!G23,'T_Scedule Rinc'!G25,'T_Scedule Rinc'!G27) -> 0.83122896 | H11: =SUM('T_Scedule Rinc'!H11,'T_Scedule Rinc'!H13,'T_Scedule Rinc'!H15,'T_Scedule Rinc'!H17,'T_Scedule Rinc'!H19,'T_Scedule Rinc'!H21,'T_Scedule Rinc'!H23,'T_Scedule Rinc'!H25,'T_Scedule Rinc'!H27) -> 0.32617845 | I11: =SUM('T_Scedule Rinc'!I11,'T_Scedule Rinc'!I13,'T_Scedule Rinc'!I15,'T_Scedule Rinc'!I17,'T_Scedule Rinc'!I19,'T_Scedule Rinc'!I21,'T_Scedule Rinc'!I23,'T_Scedule Rinc'!I25,'T_Scedule Rinc'!I27) -> 0.32617845 | J11: =SUM('T_Scedule Rinc'!J11,'T_Scedule Rinc'!J13,'T_Scedule Rinc'!J15,'T_Scedule Rinc'!J17,'T_Scedule Rinc'!J19,'T_Scedule Rinc'!J21,'T_Scedule Rinc'!J23,'T_Scedule Rinc'!J25,'T_Scedule Rinc'!J27) -> 0.32617845 | K11: =SUM('T_Scedule Rinc'!K11,'T_Scedule Rinc'!K13,'T_Scedule Rinc'!K15,'T_Scedule Rinc'!K17,'T_Scedule Rinc'!K19,'T_Scedule Rinc'!K21,'T_Scedule Rinc'!K23,'T_Scedule Rinc'!K25,'T_Scedule Rinc'!K27) -> 0.32617845 | L11: =SUM('T_Scedule Rinc'!L11,'T_Scedule Rinc'!L13,'T_Scedule Rinc'!L15,'T_Scedule Rinc'!L17,'T_Scedule Rinc'!L19,'T_Scedule Rinc'!L21,'T_Scedule Rinc'!L23,'T_Scedule Rinc'!L25,'T_Scedule Rinc'!L27) -> 1.6662458 | M11: =SUM('T_Scedule Rinc'!M11,'T_Scedule Rinc'!M13,'T_Scedule Rinc'!M15,'T_Scedule Rinc'!M17,'T_Scedule Rinc'!M19,'T_Scedule Rinc'!M21,'T_Scedule Rinc'!M23,'T_Scedule Rinc'!M25,'T_Scedule Rinc'!M27) -> 2.5803872 | P11: =SUM(E11:M11)-D11 -> 0
A12: r | E12: =SUM(Rincian_Prog!M12:M20) -> 0 | F12: =SUM(Rincian_Prog!S12:S20) -> 0 | G12: =SUM(Rincian_Prog!Y12:Y20) -> 1.3404882 | H12: =SUM(Rincian_Prog!AE12:AE20) -> 7.3068182 | I12: =SUM(Rincian_Prog!AK12:AK20) -> 0.22727273 | J12: =SUM(Rincian_Prog!AQ12:AQ20) -> 0.11363636 | K12: =SUM(Rincian_Prog!AW12:AW20) -> -8.9882155 | L12: =SUM(Rincian_Prog!BC12:BC20) -> 0 | M12: =SUM(Rincian_Prog!BI12:BI20) -> 0
B13: =Rincian_Prog!B24 -> II | C13: =Rincian_Prog!C24 -> PEKERJAAN FIT OUT INTERIOR DAN ARSITEKTUR
A14: p | B14: =Rincian_Prog!B25 -> II.A | C14: =Rincian_Prog!C25 -> Pekerjaan Ruang Staff & Resepsionis | D14: =SUM(Rincian_Prog!I27:I55) -> 35.219991 | E14: =SUM('T_Scedule Rinc'!E31,'T_Scedule Rinc'!E33,'T_Scedule Rinc'!E35,'T_Scedule Rinc'!E37,'T_Scedule Rinc'!E39,'T_Scedule Rinc'!E41,'T_Scedule Rinc'!E43) -> 0 | F14: =SUM('T_Scedule Rinc'!F31,'T_Scedule Rinc'!F33,'T_Scedule Rinc'!F35,'T_Scedule Rinc'!F37,'T_Scedule Rinc'!F39,'T_Scedule Rinc'!F41,'T_Scedule Rinc'!F43) -> 0.80964657 | G14: =SUM('T_Scedule Rinc'!G31,'T_Scedule Rinc'!G33,'T_Scedule Rinc'!G35,'T_Scedule Rinc'!G37,'T_Scedule Rinc'!G39,'T_Scedule Rinc'!G41,'T_Scedule Rinc'!G43) -> 3.2385863 | H14: =SUM('T_Scedule Rinc'!H31,'T_Scedule Rinc'!H33,'T_Scedule Rinc'!H35,'T_Scedule Rinc'!H37,'T_Scedule Rinc'!H39,'T_Scedule Rinc'!H41,'T_Scedule Rinc'!H43) -> 0 | I14: =SUM('T_Scedule Rinc'!I31,'T_Scedule Rinc'!I33,'T_Scedule Rinc'!I35,'T_Scedule Rinc'!I37,'T_Scedule Rinc'!I39,'T_Scedule Rinc'!I41,'T_Scedule Rinc'!I43) -> 0 | J14: =SUM('T_Scedule Rinc'!J31,'T_Scedule Rinc'!J33,'T_Scedule Rinc'!J35,'T_Scedule Rinc'!J37,'T_Scedule Rinc'!J39,'T_Scedule Rinc'!J41,'T_Scedule Rinc'!J43) -> 4.431089 | K14: =SUM('T_Scedule Rinc'!K31,'T_Scedule Rinc'!K33,'T_Scedule Rinc'!K35,'T_Scedule Rinc'!K37,'T_Scedule Rinc'!K39,'T_Scedule Rinc'!K41,'T_Scedule Rinc'!K43) -> 6.7478317 | L14: =SUM('T_Scedule Rinc'!L31,'T_Scedule Rinc'!L33,'T_Scedule Rinc'!L35,'T_Scedule Rinc'!L37,'T_Scedule Rinc'!L39,'T_Scedule Rinc'!L41,'T_Scedule Rinc'!L43) -> 15.893174 | M14: =SUM('T_Scedule Rinc'!M31,'T_Scedule Rinc'!M33,'T_Scedule Rinc'!M35,'T_Scedule Rinc'!M37,'T_Scedule Rinc'!M39,'T_Scedule Rinc'!M41,'T_Scedule Rinc'!M43) -> 4.0996633 | P14: =SUM(E14:M14)-D14 -> 0
A15: r | E15: =SUM(Rincian_Prog!M27:M55) -> 0 | F15: =SUM(Rincian_Prog!S27:S55) -> 0 | G15: =SUM(Rincian_Prog!Y27:Y55) -> 2.0241164 | H15: =SUM(Rincian_Prog!AE27:AE55) -> 6.4552054 | I15: =SUM(Rincian_Prog!AK27:AK55) -> 3.3233167 | J15: =SUM(Rincian_Prog!AQ27:AQ55) -> 4.8682209 | K15: =SUM(Rincian_Prog!AW27:AW55) -> -16.670859 | L15: =SUM(Rincian_Prog!BC27:BC55) -> 0 | M15: =SUM(Rincian_Prog!BI27:BI55) -> 0
A16: p | B16: =Rincian_Prog!B60 -> II.B | C16: =Rincian_Prog!C60 -> Pekerjaan Ruang VIP | D16: =SUM(Rincian_Prog!I62:I90) -> 10.484627 | E16: =SUM('T_Scedule Rinc'!E46,'T_Scedule Rinc'!E48,'T_Scedule Rinc'!E50,'T_Scedule Rinc'!E52,'T_Scedule Rinc'!E54,'T_Scedule Rinc'!E56,'T_Scedule Rinc'!E58,'T_Scedule Rinc'!E60) -> 0 | F16: =SUM('T_Scedule Rinc'!F46,'T_Scedule Rinc'!F48,'T_Scedule Rinc'!F50,'T_Scedule Rinc'!F52,'T_Scedule Rinc'!F54,'T_Scedule Rinc'!F56,'T_Scedule Rinc'!F58,'T_Scedule Rinc'!F60) -> 0 | G16: =SUM('T_Scedule Rinc'!G46,'T_Scedule Rinc'!G48,'T_Scedule Rinc'!G50,'T_Scedule Rinc'!G52,'T_Scedule Rinc'!G54,'T_Scedule Rinc'!G56,'T_Scedule Rinc'!G58,'T_Scedule Rinc'!G60) -> 0.43703636 | H16: =SUM('T_Scedule Rinc'!H46,'T_Scedule Rinc'!H48,'T_Scedule Rinc'!H50,'T_Scedule Rinc'!H52,'T_Scedule Rinc'!H54,'T_Scedule Rinc'!H56,'T_Scedule Rinc'!H58,'T_Scedule Rinc'!H60) -> 1.8046279 | I16: =SUM('T_Scedule Rinc'!I46,'T_Scedule Rinc'!I48,'T_Scedule Rinc'!I50,'T_Scedule Rinc'!I52,'T_Scedule Rinc'!I54,'T_Scedule Rinc'!I56,'T_Scedule Rinc'!I58,'T_Scedule Rinc'!I60) -> 0 | J16: =SUM('T_Scedule Rinc'!J46,'T_Scedule Rinc'!J48,'T_Scedule Rinc'!J50,'T_Scedule Rinc'!J52,'T_Scedule Rinc'!J54,'T_Scedule Rinc'!J56,'T_Scedule Rinc'!J58,'T_Scedule Rinc'!J60) -> 0 | K16: =SUM('T_Scedule Rinc'!K46,'T_Scedule Rinc'!K48,'T_Scedule Rinc'!K50,'T_Scedule Rinc'!K52,'T_Scedule Rinc'!K54,'T_Scedule Rinc'!K56,'T_Scedule Rinc'!K58,'T_Scedule Rinc'!K60) -> 2.717583 | L16: =SUM('T_Scedule Rinc'!L46,'T_Scedule Rinc'!L48,'T_Scedule Rinc'!L50,'T_Scedule Rinc'!L52,'T_Scedule Rinc'!L54,'T_Scedule Rinc'!L56,'T_Scedule Rinc'!L58,'T_Scedule Rinc'!L60) -> 5.5253796 | M16: =SUM('T_Scedule Rinc'!M46,'T_Scedule Rinc'!M48,'T_Scedule Rinc'!M50,'T_Scedule Rinc'!M52,'T_Scedule Rinc'!M54,'T_Scedule Rinc'!M56,'T_Scedule Rinc'!M58,'T_Scedule Rinc'!M60) -> 0 | P16: =SUM(E16:M16)-D16 -> 0
A17: r | E17: =SUM(Rincian_Prog!M62:M90) -> 0 | F17: =SUM(Rincian_Prog!S62:S90) -> 0 | G17: =SUM(Rincian_Prog!Y62:Y90) -> 0.21851818 | H17: =SUM(Rincian_Prog!AE62:AE90) -> 0.69688667 | I17: =SUM(Rincian_Prog!AK62:AK90) -> 1.8024787 | J17: =SUM(Rincian_Prog!AQ62:AQ90) -> 3.1517491 | K17: =SUM(Rincian_Prog!AW62:AW990) -> -72.944467 | L17: =SUM(Rincian_Prog!BC62:BC90) -> 0 | M17: =SUM(Rincian_Prog!BI62:BI90) -> 0
A18: p | B18: =Rincian_Prog!B94 -> II.C | C18: =Rincian_Prog!C94 -> Pekerjaan Ruang Rapat Umum | D18: =SUM(Rincian_Prog!I96:I125) -> 10.839365 | E18: =SUM('T_Scedule Rinc'!E63,'T_Scedule Rinc'!E65,'T_Scedule Rinc'!E67,'T_Scedule Rinc'!E69,'T_Scedule Rinc'!E71,'T_Scedule Rinc'!E73,'T_Scedule Rinc'!E75,'T_Scedule Rinc'!E77) -> 0 | F18: =SUM('T_Scedule Rinc'!F63,'T_Scedule Rinc'!F65,'T_Scedule Rinc'!F67,'T_Scedule Rinc'!F69,'T_Scedule Rinc'!F71,'T_Scedule Rinc'!F73,'T_Scedule Rinc'!F75,'T_Scedule Rinc'!F77) -> 0 | G18: =SUM('T_Scedule Rinc'!G63,'T_Scedule Rinc'!G65,'T_Scedule Rinc'!G67,'T_Scedule Rinc'!G69,'T_Scedule Rinc'!G71,'T_Scedule Rinc'!G73,'T_Scedule Rinc'!G75,'T_Scedule Rinc'!G77) -> 0.43703636 | H18: =SUM('T_Scedule Rinc'!H63,'T_Scedule Rinc'!H65,'T_Scedule Rinc'!H67,'T_Scedule Rinc'!H69,'T_Scedule Rinc'!H71,'T_Scedule Rinc'!H73,'T_Scedule Rinc'!H75,'T_Scedule Rinc'!H77) -> 0.52261616 | I18: =SUM('T_Scedule Rinc'!I63,'T_Scedule Rinc'!I65,'T_Scedule Rinc'!I67,'T_Scedule Rinc'!I69,'T_Scedule Rinc'!I71,'T_Scedule Rinc'!I73,'T_Scedule Rinc'!I75,'T_Scedule Rinc'!I77) -> 0 | J18: =SUM('T_Scedule Rinc'!J63,'T_Scedule Rinc'!J65,'T_Scedule Rinc'!J67,'T_Scedule Rinc'!J69,'T_Scedule Rinc'!J71,'T_Scedule Rinc'!J73,'T_Scedule Rinc'!J75,'T_Scedule Rinc'!J77) -> 0.0093883838 | K18: =SUM('T_Scedule Rinc'!K63,'T_Scedule Rinc'!K65,'T_Scedule Rinc'!K67,'T_Scedule Rinc'!K69,'T_Scedule Rinc'!K71,'T_Scedule Rinc'!K73,'T_Scedule Rinc'!K75,'T_Scedule Rinc'!K77) -> 3.7753258 | L18: =SUM('T_Scedule Rinc'!L63,'T_Scedule Rinc'!L65,'T_Scedule Rinc'!L67,'T_Scedule Rinc'!L69,'T_Scedule Rinc'!L71,'T_Scedule Rinc'!L73,'T_Scedule Rinc'!L75,'T_Scedule Rinc'!L77) -> 4.9117663 | M18: =SUM('T_Scedule Rinc'!M63,'T_Scedule Rinc'!M65,'T_Scedule Rinc'!M67,'T_Scedule Rinc'!M69,'T_Scedule Rinc'!M71,'T_Scedule Rinc'!M73,'T_Scedule Rinc'!M75,'T_Scedule Rinc'!M77) -> 1.1832323 | P18: =SUM(E18:M18)-D18 -> 0
A19: r | E19: =SUM(Rincian_Prog!M96:M125) -> 0 | F19: =SUM(Rincian_Prog!S96:S125) -> 0 | G19: =SUM(Rincian_Prog!Y96:Y125) -> 0.21851818 | H19: =SUM(Rincian_Prog!AE96:AE125) -> 0.69688667 | I19: =SUM(Rincian_Prog!AK96:AK125) -> 0.77686929 | J19: =SUM(Rincian_Prog!AQ96:AQ125) -> 3.5996575 | K19: =SUM(Rincian_Prog!AW96:AW125) -> -5.2919316 | L19: =SUM(Rincian_Prog!BC96:BC125) -> 0 | M19: =SUM(Rincian_Prog!BI96:BI125) -> 0
